Workbook

Sheet upload
A1: CHƯƠNG I. QUY ĐỊNH CHUNG VÀ QUY TẮC GIAO THÔNG ĐƯỜNG BỘ | C1: 0 | D1: Câu | E1: Nội dung câu | F1: Hình ảnh | G1: Lựa chọn 1 | H1: Lựa chọn 2 | I1: Lựa chọn 3 | J1: Lựa chọn 4 | K1: Đáp án | L1: Câu liệt | M1: Giải thích | N1: Hình ảnh giải thích | O1: không xáo đáp án | P1: STT | Q1: Nối
A2: Câu 1. Phần của đường bộ được sử dụng cho phương tiện giao thông đường bộ đi lại là gì? | C2: =IFERROR(COUNTIFS($A$1:A2,"Câu "&"*")-MID(A2,5,FIND(".",A2,1)-5),0) -> 0 | D2: =IF(LEFT(A2,3)="Câu",VALUE(MID(A2,5,FIND(".",A2,1)-5)),"") -> 1 | E2: =SUBSTITUTE(IF(LEFT(A2,3)="Câu",MID(A2,FIND(".",A2,1)+2,LEN(A2)),""),CHAR(34),CHAR(92)&CHAR(34)) -> Phần của đường bộ được sử dụng cho phương tiện giao thông đường bộ đi lại là gì? | G2: =SUBSTITUTE(B3,CHAR(34),CHAR(92)&CHAR(34)) -> Phần mặt đường và lề đường. | H2: =SUBSTITUTE(B4,CHAR(34),CHAR(92)&CHAR(34)) -> Phần đường xe chạy. | I2: =SUBSTITUTE(IF(LEFT(A5,3)="Câu","",B5),CHAR(34),CHAR(92)&CHAR(34)) -> Phần đường xe cơ giới. | J2: =SUBSTITUTE(IF(OR(LEFT(A6,3)="Câu",I2=""),"",IF(B6=0,"",B6)),CHAR(34),CHAR(92)&CHAR(34)) | K2: =SUBSTITUTE(SUBSTITUTE(SUBSTITUTE(SUBSTITUTE(IFERROR(VLOOKUP("Câu "&D2&".",dapan!$E:$J,6,0),""),"1","A"),"2","B"),"3","C"),"4","D") -> B | O2: x | P2: =D2 -> 1 | Q2: =IF(D2="","",CHAR(123)&CHAR(34)&"num"&CHAR(34)&":"&P2&","&CHAR(34)&"id"&CHAR(34)&":"&D2&"," &CHAR(34)&"q"&CHAR(34)&":"&CHAR(34)&E2&CHAR(34)&"," &IF(F2="","",CHAR(34)&"img"&CHAR(34)&":"&CHAR(34)&F2&CHAR(34)&",") &CHAR(34)&"opts"&CHAR(34)&":"&CHAR(123)&CHAR(34)&"A"&CHAR(34)&":"&CHAR(34)&G2&CHAR(34)&","&CHAR(34)&"B"&CHAR(34)&":"&CHAR(34)&H2&CHAR(34) &IF(I2="","",","&CHAR(34)&"C"&CHAR(34)&":"&CHAR(34)&I2&CHAR(34))&IF(J2="","",","&CHAR(34)&"D"&CHAR(34)&":"&CHAR(34)&J2&CHAR(34))&CHAR(125)&"," &CHAR(34)&"answer"&CHAR(34)&":"&CHAR(34)&K2&CHAR(34) &IF(L2="","",","&CHAR(34)&"danger"&CHAR(34)&":"&CHAR(34)&"true"&CHAR(34)) &IF(M2="","",","&CHAR(34)&"explain"&CHAR(34)&":"&CHAR(34)&M2&CHAR(34)) &IF(N2="","",","&CHAR(34)&"explainImg"&CHAR(34)&":"&CHAR(34)&N2&CHAR(34)) &IF(O2="","",","&CHAR(34)&"shuffle"&CHAR(34)&":"&CHAR(34)&"false"&CHAR(34))&CHAR(125)&",") -> {"num":1,"id":1,"q":"Phần của đường bộ được sử dụng cho phương tiện giao thông đường bộ đi lại là gì?","opts":{"A":"Phần mặt đường và lề đường.","B":"Phần đường xe chạy.","C":"Phần đường xe cơ giới."},"answer":"B","shuffle":"false"},
A3: 1 | B3: Phần mặt đường và lề đường. | C3: =IFERROR(COUNTIFS($A$1:A3,"Câu "&"*")-MID(A3,5,FIND(".",A3,1)-5),0) -> 0 | D3: =IF(LEFT(A3,3)="Câu",VALUE(MID(A3,5,FIND(".",A3,1)-5)),"") | E3: =SUBSTITUTE(IF(LEFT(A3,3)="Câu",MID(A3,FIND(".",A3,1)+2,LEN(A3)),""),CHAR(34),CHAR(92)&CHAR(34)) | G3: =SUBSTITUTE(B4,CHAR(34),CHAR(92)&CHAR(34)) -> Phần đường xe chạy. | H3: =SUBSTITUTE(B5,CHAR(34),CHAR(92)&CHAR(34)) -> Phần đường xe cơ giới. | I3: =SUBSTITUTE(IF(LEFT(A6,3)="Câu","",B6),CHAR(34),CHAR(92)&CHAR(34)) | J3: =SUBSTITUTE(IF(OR(LEFT(A7,3)="Câu",I3=""),"",IF(B7=0,"",B7)),CHAR(34),CHAR(92)&CHAR(34)) | K3: =SUBSTITUTE(SUBSTITUTE(SUBSTITUTE(SUBSTITUTE(IFERROR(VLOOKUP("Câu "&D3&".",dapan!$E:$J,6,0),""),"1","A"),"2","B"),"3","C"),"4","D") | P3: =D3 | Q3: =IF(D3="","",CHAR(123)&CHAR(34)&"num"&CHAR(34)&":"&P3&","&CHAR(34)&"id"&CHAR(34)&":"&D3&"," &CHAR(34)&"q"&CHAR(34)&":"&CHAR(34)&E3&CHAR(34)&"," &IF(F3="","",CHAR(34)&"img"&CHAR(34)&":"&CHAR(34)&F3&CHAR(34)&",") &CHAR(34)&"opts"&CHAR(34)&":"&CHAR(123)&CHAR(34)&"A"&CHAR(34)&":"&CHAR(34)&G3&CHAR(34)&","&CHAR(34)&"B"&CHAR(34)&":"&CHAR(34)&H3&CHAR(34) &IF(I3="","",","&CHAR(34)&"C"&CHAR(34)&":"&CHAR(34)&I3&CHAR(34))&IF(J3="","",","&CHAR(34)&"D"&CHAR(34)&":"&CHAR(34)&J3&CHAR(34))&CHAR(125)&"," &CHAR(34)&"answer"&CHAR(34)&":"&CHAR(34)&K3&CHAR(34) &IF(L3="","",","&CHAR(34)&"danger"&CHAR(34)&":"&CHAR(34)&"true"&CHAR(34)) &IF(M3="","",","&CHAR(34)&"explain"&CHAR(34)&":"&CHAR(34)&M3&CHAR(34)) &IF(N3="","",","&CHAR(34)&"explainImg"&CHAR(34)&":"&CHAR(34)&N3&CHAR(34)) &IF(O3="","",","&CHAR(34)&"shuffle"&CHAR(34)&":"&CHAR(34)&"false"&CHAR(34))&CHAR(125)&",")
A4: 2 | B4: Phần đường xe chạy. | C4: =IFERROR(COUNTIFS($A$1:A4,"Câu "&"*")-MID(A4,5,FIND(".",A4,1)-5),0) -> 0 | D4: =IF(LEFT(A4,3)="Câu",VALUE(MID(A4,5,FIND(".",A4,1)-5)),"") | E4: =SUBSTITUTE(IF(LEFT(A4,3)="Câu",MID(A4,FIND(".",A4,1)+2,LEN(A4)),""),CHAR(34),CHAR(92)&CHAR(34)) | G4: =SUBSTITUTE(B5,CHAR(34),CHAR(92)&CHAR(34)) -> Phần đường xe cơ giới. | H4: =SUBSTITUTE(B6,CHAR(34),CHAR(92)&CHAR(34)) | I4: =SUBSTITUTE(IF(LEFT(A7,3)="Câu","",B7),CHAR(34),CHAR(92)&CHAR(34)) -> Là một phần của phần đường xe chạy được chia theo chiều dọc của đường, sử dụng cho xe chạy. | J4: =SUBSTITUTE(IF(OR(LEFT(A8,3)="Câu",I4=""),"",IF(B8=0,"",B8)),CHAR(34),CHAR(92)&CHAR(34)) -> Là một phần của phần đường xe chạy được chia theo chiều dọc của đường, có đủ chiều rộng cho xe chạy an toàn. | K4: =SUBSTITUTE(SUBSTITUTE(SUBSTITUTE(SUBSTITUTE(IFERROR(VLOOKUP("Câu "&D4&".",dapan!$E:$J,6,0),""),"1","A"),"2","B"),"3","C"),"4","D") | P4: =D4 | Q4: =IF(D4="","",CHAR(123)&CHAR(34)&"num"&CHAR(34)&":"&P4&","&CHAR(34)&"id"&CHAR(34)&":"&D4&"," &CHAR(34)&"q"&CHAR(34)&":"&CHAR(34)&E4&CHAR(34)&"," &IF(F4="","",CHAR(34)&"img"&CHAR(34)&":"&CHAR(34)&F4&CHAR(34)&",") &CHAR(34)&"opts"&CHAR(34)&":"&CHAR(123)&CHAR(34)&"A"&CHAR(34)&":"&CHAR(34)&G4&CHAR(34)&","&CHAR(34)&"B"&CHAR(34)&":"&CHAR(34)&H4&CHAR(34) &IF(I4="","",","&CHAR(34)&"C"&CHAR(34)&":"&CHAR(34)&I4&CHAR(34))&IF(J4="","",","&CHAR(34)&"D"&CHAR(34)&":"&CHAR(34)&J4&CHAR(34))&CHAR(125)&"," &CHAR(34)&"answer"&CHAR(34)&":"&CHAR(34)&K4&CHAR(34) &IF(L4="","",","&CHAR(34)&"danger"&CHAR(34)&":"&CHAR(34)&"true"&CHAR(34)) &IF(M4="","",","&CHAR(34)&"explain"&CHAR(34)&":"&CHAR(34)&M4&CHAR(34)) &IF(N4="","",","&CHAR(34)&"explainImg"&CHAR(34)&":"&CHAR(34)&N4&CHAR(34)) &IF(O4="","",","&CHAR(34)&"shuffle"&CHAR(34)&":"&CHAR(34)&"false"&CHAR(34))&CHAR(125)&",")
A5: 3 | B5: Phần đường xe cơ giới. | C5: =IFERROR(COUNTIFS($A$1:A5,"Câu "&"*")-MID(A5,5,FIND(".",A5,1)-5),0) -> 0 | D5: =IF(LEFT(A5,3)="Câu",VALUE(MID(A5,5,FIND(".",A5,1)-5)),"") | E5: =SUBSTITUTE(IF(LEFT(A5,3)="Câu",MID(A5,FIND(".",A5,1)+2,LEN(A5)),""),CHAR(34),CHAR(92)&CHAR(34)) | G5: =SUBSTITUTE(B6,CHAR(34),CHAR(92)&CHAR(34)) | H5: =SUBSTITUTE(B7,CHAR(34),CHAR(92)&CHAR(34)) -> Là một phần của phần đường xe chạy được chia theo chiều dọc của đường, sử dụng cho xe chạy. | I5: =SUBSTITUTE(IF(LEFT(A8,3)="Câu","",B8),CHAR(34),CHAR(92)&CHAR(34)) -> Là một phần của phần đường xe chạy được chia theo chiều dọc của đường, có đủ chiều rộng cho xe chạy an toàn. | J5: =SUBSTITUTE(IF(OR(LEFT(A9,3)="Câu",I5=""),"",IF(B9=0,"",B9)),CHAR(34),CHAR(92)&CHAR(34)) -> Là đường cho xe ô tô chạy, dừng, đỗ an toàn. | K5: =SUBSTITUTE(SUBSTITUTE(SUBSTITUTE(SUBSTITUTE(IFERROR(VLOOKUP("Câu "&D5&".",dapan!$E:$J,6,0),""),"1","A"),"2","B"),"3","C"),"4","D") | P5: =D5 | Q5: =IF(D5="","",CHAR(123)&CHAR(34)&"num"&CHAR(34)&":"&P5&","&CHAR(34)&"id"&CHAR(34)&":"&D5&"," &CHAR(34)&"q"&CHAR(34)&":"&CHAR(34)&E5&CHAR(34)&"," &IF(F5="","",CHAR(34)&"img"&CHAR(34)&":"&CHAR(34)&F5&CHAR(34)&",") &CHAR(34)&"opts"&CHAR(34)&":"&CHAR(123)&CHAR(34)&"A"&CHAR(34)&":"&CHAR(34)&G5&CHAR(34)&","&CHAR(34)&"B"&CHAR(34)&":"&CHAR(34)&H5&CHAR(34) &IF(I5="","",","&CHAR(34)&"C"&CHAR(34)&":"&CHAR(34)&I5&CHAR(34))&IF(J5="","",","&CHAR(34)&"D"&CHAR(34)&":"&CHAR(34)&J5&CHAR(34))&CHAR(125)&"," &CHAR(34)&"answer"&CHAR(34)&":"&CHAR(34)&K5&CHAR(34) &IF(L5="","",","&CHAR(34)&"danger"&CHAR(34)&":"&CHAR(34)&"true"&CHAR(34)) &IF(M5="","",","&CHAR(34)&"explain"&CHAR(34)&":"&CHAR(34)&M5&CHAR(34)) &IF(N5="","",","&CHAR(34)&"explainImg"&CHAR(34)&":"&CHAR(34)&N5&CHAR(34)) &IF(O5="","",","&CHAR(34)&"shuffle"&CHAR(34)&":"&CHAR(34)&"false"&CHAR(34))&CHAR(125)&",")
A6: Câu 2. Làn đường là gì? | C6: =IFERROR(COUNTIFS($A$1:A6,"Câu "&"*")-MID(A6,5,FIND(".",A6,1)-5),0) -> 0 | D6: =IF(LEFT(A6,3)="Câu",VALUE(MID(A6,5,FIND(".",A6,1)-5)),"") -> 2 | E6: =SUBSTITUTE(IF(LEFT(A6,3)="Câu",MID(A6,FIND(".",A6,1)+2,LEN(A6)),""),CHAR(34),CHAR(92)&CHAR(34)) -> Làn đường là gì? | G6: =SUBSTITUTE(B7,CHAR(34),CHAR(92)&CHAR(34)) -> Là một phần của phần đường xe chạy được chia theo chiều dọc của đường, sử dụng cho xe chạy. | H6: =SUBSTITUTE(B8,CHAR(34),CHAR(92)&CHAR(34)) -> Là một phần của phần đường xe chạy được chia theo chiều dọc của đường, có đủ chiều rộng cho xe chạy an toàn. | I6: =SUBSTITUTE(IF(LEFT(A9,3)="Câu","",B9),CHAR(34),CHAR(92)&CHAR(34)) -> Là đường cho xe ô tô chạy, dừng, đỗ an toàn. | J6: =SUBSTITUTE(IF(OR(LEFT(A10,3)="Câu",I6=""),"",IF(B10=0,"",B10)),CHAR(34),CHAR(92)&CHAR(34)) | K6: =SUBSTITUTE(SUBSTITUTE(SUBSTITUTE(SUBSTITUTE(IFERROR(VLOOKUP("Câu "&D6&".",dapan!$E:$J,6,0),""),"1","A"),"2","B"),"3","C"),"4","D") -> B | P6: =D6 -> 2 | Q6: =IF(D6="","",CHAR(123)&CHAR(34)&"num"&CHAR(34)&":"&P6&","&CHAR(34)&"id"&CHAR(34)&":"&D6&"," &CHAR(34)&"q"&CHAR(34)&":"&CHAR(34)&E6&CHAR(34)&"," &IF(F6="","",CHAR(34)&"img"&CHAR(34)&":"&CHAR(34)&F6&CHAR(34)&",") &CHAR(34)&"opts"&CHAR(34)&":"&CHAR(123)&CHAR(34)&"A"&CHAR(34)&":"&CHAR(34)&G6&CHAR(34)&","&CHAR(34)&"B"&CHAR(34)&":"&CHAR(34)&H6&CHAR(34) &IF(I6="","",","&CHAR(34)&"C"&CHAR(34)&":"&CHAR(34)&I6&CHAR(34))&IF(J6="","",","&CHAR(34)&"D"&CHAR(34)&":"&CHAR(34)&J6&CHAR(34))&CHAR(125)&"," &CHAR(34)&"answer"&CHAR(34)&":"&CHAR(34)&K6&CHAR(34) &IF(L6="","",","&CHAR(34)&"danger"&CHAR(34)&":"&CHAR(34)&"true"&CHAR(34)) &IF(M6="","",","&CHAR(34)&"explain"&CHAR(34)&":"&CHAR(34)&M6&CHAR(34)) &IF(N6="","",","&CHAR(34)&"explainImg"&CHAR(34)&":"&CHAR(34)&N6&CHAR(34)) &IF(O6="","",","&CHAR(34)&"shuffle"&CHAR(34)&":"&CHAR(34)&"false"&CHAR(34))&CHAR(125)&",") -> {"num":2,"id":2,"q":"Làn đường là gì?","opts":{"A":"Là một phần của phần đường xe chạy được chia theo chiều dọc của đường, sử dụng cho xe chạy.","B":"Là một phần của phần đường xe chạy được chia theo chiều dọc của đường, có đủ chiều rộng cho xe chạy an toàn.","C":"Là đường cho xe ô tô chạy, dừng, đỗ an toàn."},"answer":"B"}, | R6: =CHAR(S6) | S6: 10
A7: 1 | B7: Là một phần của phần đường xe chạy được chia theo chiều dọc của đường, sử dụng cho xe chạy. | C7: =IFERROR(COUNTIFS($A$1:A7,"Câu "&"*")-MID(A7,5,FIND(".",A7,1)-5),0) -> 0 | D7: =IF(LEFT(A7,3)="Câu",VALUE(MID(A7,5,FIND(".",A7,1)-5)),"") | E7: =SUBSTITUTE(IF(LEFT(A7,3)="Câu",MID(A7,FIND(".",A7,1)+2,LEN(A7)),""),CHAR(34),CHAR(92)&CHAR(34)) | G7: =SUBSTITUTE(B8,CHAR(34),CHAR(92)&CHAR(34)) -> Là một phần của phần đường xe chạy được chia theo chiều dọc của đường, có đủ chiều rộng cho xe chạy an toàn. | H7: =SUBSTITUTE(B9,CHAR(34),CHAR(92)&CHAR(34)) -> Là đường cho xe ô tô chạy, dừng, đỗ an toàn. | I7: =SUBSTITUTE(IF(LEFT(A10,3)="Câu","",B10),CHAR(34),CHAR(92)&CHAR(34)) | J7: =SUBSTITUTE(IF(OR(LEFT(A11,3)="Câu",I7=""),"",IF(B11=0,"",B11)),CHAR(34),CHAR(92)&CHAR(34)) | K7: =SUBSTITUTE(SUBSTITUTE(SUBSTITUTE(SUBSTITUTE(IFERROR(VLOOKUP("Câu "&D7&".",dapan!$E:$J,6,0),""),"1","A"),"2","B"),"3","C"),"4","D") | P7: =D7 | Q7: =IF(D7="","",CHAR(123)&CHAR(34)&"num"&CHAR(34)&":"&P7&","&CHAR(34)&"id"&CHAR(34)&":"&D7&"," &CHAR(34)&"q"&CHAR(34)&":"&CHAR(34)&E7&CHAR(34)&"," &IF(F7="","",CHAR(34)&"img"&CHAR(34)&":"&CHAR(34)&F7&CHAR(34)&",") &CHAR(34)&"opts"&CHAR(34)&":"&CHAR(123)&CHAR(34)&"A"&CHAR(34)&":"&CHAR(34)&G7&CHAR(34)&","&CHAR(34)&"B"&CHAR(34)&":"&CHAR(34)&H7&CHAR(34) &IF(I7="","",","&CHAR(34)&"C"&CHAR(34)&":"&CHAR(34)&I7&CHAR(34))&IF(J7="","",","&CHAR(34)&"D"&CHAR(34)&":"&CHAR(34)&J7&CHAR(34))&CHAR(125)&"," &CHAR(34)&"answer"&CHAR(34)&":"&CHAR(34)&K7&CHAR(34) &IF(L7="","",","&CHAR(34)&"danger"&CHAR(34)&":"&CHAR(34)&"true"&CHAR(34)) &IF(M7="","",","&CHAR(34)&"explain"&CHAR(34)&":"&CHAR(34)&M7&CHAR(34)) &IF(N7="","",","&CHAR(34)&"explainImg"&CHAR(34)&":"&CHAR(34)&N7&CHAR(34)) &IF(O7="","",","&CHAR(34)&"shuffle"&CHAR(34)&":"&CHAR(34)&"false"&CHAR(34))&CHAR(125)&",") | R7: =CHAR(S7) -> _x000B_ | S7: =S6+1 -> 11
A8: 2 | B8: Là một phần của phần đường xe chạy được chia theo chiều dọc của đường, có đủ chiều rộng cho xe chạy an toàn. | C8: =IFERROR(COUNTIFS($A$1:A8,"Câu "&"*")-MID(A8,5,FIND(".",A8,1)-5),0) -> 0 | D8: =IF(LEFT(A8,3)="Câu",VALUE(MID(A8,5,FIND(".",A8,1)-5)),"") | E8: =SUBSTITUTE(IF(LEFT(A8,3)="Câu",MID(A8,FIND(".",A8,1)+2,LEN(A8)),""),CHAR(34),CHAR(92)&CHAR(34)) | G8: =SUBSTITUTE(B9,CHAR(34),CHAR(92)&CHAR(34)) -> Là đường cho xe ô tô chạy, dừng, đỗ an toàn. | H8: =SUBSTITUTE(B10,CHAR(34),CHAR(92)&CHAR(34)) | I8: =SUBSTITUTE(IF(LEFT(A11,3)="Câu","",B11),CHAR(34),CHAR(92)&CHAR(34)) -> Khổ giới hạn của đường bộ là khoảng trống có kích thước giới hạn về chiều rộng, chiều cao của đường bộ để các xe, bao gồm cả hàng hoá xếp trên xe đi qua được an toàn và được xác định theo quy chuẩn, tiêu chuẩn kỹ thuật của đường bộ. | J8: =SUBSTITUTE(IF(OR(LEFT(A12,3)="Câu",I8=""),"",IF(B12=0,"",B12)),CHAR(34),CHAR(92)&CHAR(34)) -> Là khoảng trống có kích thước giới hạn về chiều rộng của đường, cầu, bến phà, hầm trên đường bộ để các xe kể cả hàng hóa xếp trên xe đi qua được an toàn. | K8: =SUBSTITUTE(SUBSTITUTE(SUBSTITUTE(SUBSTITUTE(IFERROR(VLOOKUP("Câu "&D8&".",dapan!$E:$J,6,0),""),"1","A"),"2","B"),"3","C"),"4","D") | P8: =D8 | Q8: =IF(D8="","",CHAR(123)&CHAR(34)&"num"&CHAR(34)&":"&P8&","&CHAR(34)&"id"&CHAR(34)&":"&D8&"," &CHAR(34)&"q"&CHAR(34)&":"&CHAR(34)&E8&CHAR(34)&"," &IF(F8="","",CHAR(34)&"img"&CHAR(34)&":"&CHAR(34)&F8&CHAR(34)&",") &CHAR(34)&"opts"&CHAR(34)&":"&CHAR(123)&CHAR(34)&"A"&CHAR(34)&":"&CHAR(34)&G8&CHAR(34)&","&CHAR(34)&"B"&CHAR(34)&":"&CHAR(34)&H8&CHAR(34) &IF(I8="","",","&CHAR(34)&"C"&CHAR(34)&":"&CHAR(34)&I8&CHAR(34))&IF(J8="","",","&CHAR(34)&"D"&CHAR(34)&":"&CHAR(34)&J8&CHAR(34))&CHAR(125)&"," &CHAR(34)&"answer"&CHAR(34)&":"&CHAR(34)&K8&CHAR(34) &IF(L8="","",","&CHAR(34)&"danger"&CHAR(34)&":"&CHAR(34)&"true"&CHAR(34)) &IF(M8="","",","&CHAR(34)&"explain"&CHAR(34)&":"&CHAR(34)&M8&CHAR(34)) &IF(N8="","",","&CHAR(34)&"explainImg"&CHAR(34)&":"&CHAR(34)&N8&CHAR(34)) &IF(O8="","",","&CHAR(34)&"shuffle"&CHAR(34)&":"&CHAR(34)&"false"&CHAR(34))&CHAR(125)&",") | R8: =CHAR(S8) -> _x000C_ | S8: =S7+1 -> 12
A9: 3 | B9: Là đường cho xe ô tô chạy, dừng, đỗ an toàn. | C9: =IFERROR(COUNTIFS($A$1:A9,"Câu "&"*")-MID(A9,5,FIND(".",A9,1)-5),0) -> 0 | D9: =IF(LEFT(A9,3)="Câu",VALUE(MID(A9,5,FIND(".",A9,1)-5)),"") | E9: =SUBSTITUTE(IF(LEFT(A9,3)="Câu",MID(A9,FIND(".",A9,1)+2,LEN(A9)),""),CHAR(34),CHAR(92)&CHAR(34)) | G9: =SUBSTITUTE(B10,CHAR(34),CHAR(92)&CHAR(34)) | H9: =SUBSTITUTE(B11,CHAR(34),CHAR(92)&CHAR(34)) -> Khổ giới hạn của đường bộ là khoảng trống có kích thước giới hạn về chiều rộng, chiều cao của đường bộ để các xe, bao gồm cả hàng hoá xếp trên xe đi qua được an toàn và được xác định theo quy chuẩn, tiêu chuẩn kỹ thuật của đường bộ. | I9: =SUBSTITUTE(IF(LEFT(A12,3)="Câu","",B12),CHAR(34),CHAR(92)&CHAR(34)) -> Là khoảng trống có kích thước giới hạn về chiều rộng của đường, cầu, bến phà, hầm trên đường bộ để các xe kể cả hàng hóa xếp trên xe đi qua được an toàn. | J9: =SUBSTITUTE(IF(OR(LEFT(A13,3)="Câu",I9=""),"",IF(B13=0,"",B13)),CHAR(34),CHAR(92)&CHAR(34)) -> Là khoảng trống có kích thước giới hạn về chiều cao của cầu, bến phà, hầm trên đường bộ để các xe đi qua được an toàn. | K9: =SUBSTITUTE(SUBSTITUTE(SUBSTITUTE(SUBSTITUTE(IFERROR(VLOOKUP("Câu "&D9&".",dapan!$E:$J,6,0),""),"1","A"),"2","B"),"3","C"),"4","D") | P9: =D9 | Q9: =IF(D9="","",CHAR(123)&CHAR(34)&"num"&CHAR(34)&":"&P9&","&CHAR(34)&"id"&CHAR(34)&":"&D9&"," &CHAR(34)&"q"&CHAR(34)&":"&CHAR(34)&E9&CHAR(34)&"," &IF(F9="","",CHAR(34)&"img"&CHAR(34)&":"&CHAR(34)&F9&CHAR(34)&",") &CHAR(34)&"opts"&CHAR(34)&":"&CHAR(123)&CHAR(34)&"A"&CHAR(34)&":"&CHAR(34)&G9&CHAR(34)&","&CHAR(34)&"B"&CHAR(34)&":"&CHAR(34)&H9&CHAR(34) &IF(I9="","",","&CHAR(34)&"C"&CHAR(34)&":"&CHAR(34)&I9&CHAR(34))&IF(J9="","",","&CHAR(34)&"D"&CHAR(34)&":"&CHAR(34)&J9&CHAR(34))&CHAR(125)&"," &CHAR(34)&"answer"&CHAR(34)&":"&CHAR(34)&K9&CHAR(34) &IF(L9="","",","&CHAR(34)&"danger"&CHAR(34)&":"&CHAR(34)&"true"&CHAR(34)) &IF(M9="","",","&CHAR(34)&"explain"&CHAR(34)&":"&CHAR(34)&M9&CHAR(34)) &IF(N9="","",","&CHAR(34)&"explainImg"&CHAR(34)&":"&CHAR(34)&N9&CHAR(34)) &IF(O9="","",","&CHAR(34)&"shuffle"&CHAR(34)&":"&CHAR(34)&"false"&CHAR(34))&CHAR(125)&",") | R9: =CHAR(S9) -> _x000D_ | S9: =S8+1 -> 13
A10: Câu 3. Khổ giới hạn của đường bộ được hiểu như thế nào là đúng? | C10: =IFERROR(COUNTIFS($A$1:A10,"Câu "&"*")-MID(A10,5,FIND(".",A10,1)-5),0) -> 0 | D10: =IF(LEFT(A10,3)="Câu",VALUE(MID(A10,5,FIND(".",A10,1)-5)),"") -> 3 | E10: =SUBSTITUTE(IF(LEFT(A10,3)="Câu",MID(A10,FIND(".",A10,1)+2,LEN(A10)),""),CHAR(34),CHAR(92)&CHAR(34)) -> Khổ giới hạn của đường bộ được hiểu như thế nào là đúng? | G10: =SUBSTITUTE(B11,CHAR(34),CHAR(92)&CHAR(34)) -> Khổ giới hạn của đường bộ là khoảng trống có kích thước giới hạn về chiều rộng, chiều cao của đường bộ để các xe, bao gồm cả hàng hoá xếp trên xe đi qua được an toàn và được xác định theo quy chuẩn, tiêu chuẩn kỹ thuật của đường bộ. | H10: =SUBSTITUTE(B12,CHAR(34),CHAR(92)&CHAR(34)) -> Là khoảng trống có kích thước giới hạn về chiều rộng của đường, cầu, bến phà, hầm trên đường bộ để các xe kể cả hàng hóa xếp trên xe đi qua được an toàn. | I10: =SUBSTITUTE(IF(LEFT(A13,3)="Câu","",B13),CHAR(34),CHAR(92)&CHAR(34)) -> Là khoảng trống có kích thước giới hạn về chiều cao của cầu, bến phà, hầm trên đường bộ để các xe đi qua được an toàn. | J10: =SUBSTITUTE(IF(OR(LEFT(A14,3)="Câu",I10=""),"",IF(B14=0,"",B14)),CHAR(34),CHAR(92)&CHAR(34)) | K10: =SUBSTITUTE(SUBSTITUTE(SUBSTITUTE(SUBSTITUTE(IFERROR(VLOOKUP("Câu "&D10&".",dapan!$E:$J,6,0),""),"1","A"),"2","B"),"3","C"),"4","D") -> A | P10: =D10 -> 3 | Q10: =IF(D10="","",CHAR(123)&CHAR(34)&"num"&CHAR(34)&":"&P10&","&CHAR(34)&"id"&CHAR(34)&":"&D10&"," &CHAR(34)&"q"&CHAR(34)&":"&CHAR(34)&E10&CHAR(34)&"," &IF(F10="","",CHAR(34)&"img"&CHAR(34)&":"&CHAR(34)&F10&CHAR(34)&",") &CHAR(34)&"opts"&CHAR(34)&":"&CHAR(123)&CHAR(34)&"A"&CHAR(34)&":"&CHAR(34)&G10&CHAR(34)&","&CHAR(34)&"B"&CHAR(34)&":"&CHAR(34)&H10&CHAR(34) &IF(I10="","",","&CHAR(34)&"C"&CHAR(34)&":"&CHAR(34)&I10&CHAR(34))&IF(J10="","",","&CHAR(34)&"D"&CHAR(34)&":"&CHAR(34)&J10&CHAR(34))&CHAR(125)&"," &CHAR(34)&"answer"&CHAR(34)&":"&CHAR(34)&K10&CHAR(34) &IF(L10="","",","&CHAR(34)&"danger"&CHAR(34)&":"&CHAR(34)&"true"&CHAR(34)) &IF(M10="","",","&CHAR(34)&"explain"&CHAR(34)&":"&CHAR(34)&M10&CHAR(34)) &IF(N10="","",","&CHAR(34)&"explainImg"&CHAR(34)&":"&CHAR(34)&N10&CHAR(34)) &IF(O10="","",","&CHAR(34)&"shuffle"&CHAR(34)&":"&CHAR(34)&"false"&CHAR(34))&CHAR(125)&",") -> {"num":3,"id":3,"q":"Khổ giới hạn của đường bộ được hiểu như thế nào là đúng?","opts":{"A":"Khổ giới hạn của đường bộ là khoảng trống có kích thước giới hạn về chiều rộng, chiều cao của đường bộ để các xe, bao gồm cả hàng hoá xếp trên xe đi qua được an toàn và được xác định theo quy chuẩn, tiêu chuẩn kỹ thuật của đường bộ.","B":"Là khoảng trống có kích thước giới hạn về chiều rộng của đường, cầu, bến phà, hầm trên đường bộ để các xe kể cả hàng hóa xếp trên xe đi qua được an toàn.","C":"Là khoảng trống có kích thước giới hạn về chiều cao của cầu, bến phà, hầm trên đường bộ để các xe đi qua được an toàn."},"answer":"A"}, | R10: =CHAR(S10) -> _x000E_ | S10: =S9+1 -> 14
A11: 1 | B11: Khổ giới hạn của đường bộ là khoảng trống có kích thước giới hạn về chiều rộng, chiều cao của đường bộ để các xe, bao gồm cả hàng hoá xếp trên xe đi qua được an toàn và được xác định theo quy chuẩn, tiêu chuẩn kỹ thuật của đường bộ. | C11: =IFERROR(COUNTIFS($A$1:A11,"Câu "&"*")-MID(A11,5,FIND(".",A11,1)-5),0) -> 0 | D11: =IF(LEFT(A11,3)="Câu",VALUE(MID(A11,5,FIND(".",A11,1)-5)),"") | E11: =SUBSTITUTE(IF(LEFT(A11,3)="Câu",MID(A11,FIND(".",A11,1)+2,LEN(A11)),""),CHAR(34),CHAR(92)&CHAR(34)) | G11: =SUBSTITUTE(B12,CHAR(34),CHAR(92)&CHAR(34)) -> Là khoảng trống có kích thước giới hạn về chiều rộng của đường, cầu, bến phà, hầm trên đường bộ để các xe kể cả hàng hóa xếp trên xe đi qua được an toàn. | H11: =SUBSTITUTE(B13,CHAR(34),CHAR(92)&CHAR(34)) -> Là khoảng trống có kích thước giới hạn về chiều cao của cầu, bến phà, hầm trên đường bộ để các xe đi qua được an toàn. | I11: =SUBSTITUTE(IF(LEFT(A14,3)="Câu","",B14),CHAR(34),CHAR(92)&CHAR(34)) | J11: =SUBSTITUTE(IF(OR(LEFT(A15,3)="Câu",I11=""),"",IF(B15=0,"",B15)),CHAR(34),CHAR(92)&CHAR(34)) | K11: =SUBSTITUTE(SUBSTITUTE(SUBSTITUTE(SUBSTITUTE(IFERROR(VLOOKUP("Câu "&D11&".",dapan!$E:$J,6,0),""),"1","A"),"2","B"),"3","C"),"4","D") | P11: =D11 | Q11: =IF(D11="","",CHAR(123)&CHAR(34)&"num"&CHAR(34)&":"&P11&","&CHAR(34)&"id"&CHAR(34)&":"&D11&"," &CHAR(34)&"q"&CHAR(34)&":"&CHAR(34)&E11&CHAR(34)&"," &IF(F11="","",CHAR(34)&"img"&CHAR(34)&":"&CHAR(34)&F11&CHAR(34)&",") &CHAR(34)&"opts"&CHAR(34)&":"&CHAR(123)&CHAR(34)&"A"&CHAR(34)&":"&CHAR(34)&G11&CHAR(34)&","&CHAR(34)&"B"&CHAR(34)&":"&CHAR(34)&H11&CHAR(34) &IF(I11="","",","&CHAR(34)&"C"&CHAR(34)&":"&CHAR(34)&I11&CHAR(34))&IF(J11="","",","&CHAR(34)&"D"&CHAR(34)&":"&CHAR(34)&J11&CHAR(34))&CHAR(125)&"," &CHAR(34)&"answer"&CHAR(34)&":"&CHAR(34)&K11&CHAR(34) &IF(L11="","",","&CHAR(34)&"danger"&CHAR(34)&":"&CHAR(34)&"true"&CHAR(34)) &IF(M11="","",","&CHAR(34)&"explain"&CHAR(34)&":"&CHAR(34)&M11&CHAR(34)) &IF(N11="","",","&CHAR(34)&"explainImg"&CHAR(34)&":"&CHAR(34)&N11&CHAR(34)) &IF(O11="","",","&CHAR(34)&"shuffle"&CHAR(34)&":"&CHAR(34)&"false"&CHAR(34))&CHAR(125)&",") | R11: =CHAR(S11) -> _x000F_ | S11: =S10+1 -> 15
A12: 2 | B12: Là khoảng trống có kích thước giới hạn về chiều rộng của đường, cầu, bến phà, hầm trên đường bộ để các xe kể cả hàng hóa xếp trên xe đi qua được an toàn. | C12: =IFERROR(COUNTIFS($A$1:A12,"Câu "&"*")-MID(A12,5,FIND(".",A12,1)-5),0) -> 0 | D12: =IF(LEFT(A12,3)="Câu",VALUE(MID(A12,5,FIND(".",A12,1)-5)),"") | E12: =SUBSTITUTE(IF(LEFT(A12,3)="Câu",MID(A12,FIND(".",A12,1)+2,LEN(A12)),""),CHAR(34),CHAR(92)&CHAR(34)) | G12: =SUBSTITUTE(B13,CHAR(34),CHAR(92)&CHAR(34)) -> Là khoảng trống có kích thước giới hạn về chiều cao của cầu, bến phà, hầm trên đường bộ để các xe đi qua được an toàn. | H12: =SUBSTITUTE(B14,CHAR(34),CHAR(92)&CHAR(34)) | I12: =SUBSTITUTE(IF(LEFT(A15,3)="Câu","",B15),CHAR(34),CHAR(92)&CHAR(34)) -> Để phân chia các làn đường dành cho xe cơ giới và xe thô sơ trên đường cao tốc. | J12: =SUBSTITUTE(IF(OR(LEFT(A16,3)="Câu",I12=""),"",IF(B16=0,"",B16)),CHAR(34),CHAR(92)&CHAR(34)) -> Để phân chia phần đường xe chạy thành hai chiều riêng biệt hoặc để phân chia phần đường dành cho xe cơ giới và xe thô sơ hoặc của nhiều loại xe khác nhau trên cùng một chiều đường. | K12: =SUBSTITUTE(SUBSTITUTE(SUBSTITUTE(SUBSTITUTE(IFERROR(VLOOKUP("Câu "&D12&".",dapan!$E:$J,6,0),""),"1","A"),"2","B"),"3","C"),"4","D") | P12: =D12 | Q12: =IF(D12="","",CHAR(123)&CHAR(34)&"num"&CHAR(34)&":"&P12&","&CHAR(34)&"id"&CHAR(34)&":"&D12&"," &CHAR(34)&"q"&CHAR(34)&":"&CHAR(34)&E12&CHAR(34)&"," &IF(F12="","",CHAR(34)&"img"&CHAR(34)&":"&CHAR(34)&F12&CHAR(34)&",") &CHAR(34)&"opts"&CHAR(34)&":"&CHAR(123)&CHAR(34)&"A"&CHAR(34)&":"&CHAR(34)&G12&CHAR(34)&","&CHAR(34)&"B"&CHAR(34)&":"&CHAR(34)&H12&CHAR(34) &IF(I12="","",","&CHAR(34)&"C"&CHAR(34)&":"&CHAR(34)&I12&CHAR(34))&IF(J12="","",","&CHAR(34)&"D"&CHAR(34)&":"&CHAR(34)&J12&CHAR(34))&CHAR(125)&"," &CHAR(34)&"answer"&CHAR(34)&":"&CHAR(34)&K12&CHAR(34) &IF(L12="","",","&CHAR(34)&"danger"&CHAR(34)&":"&CHAR(34)&"true"&CHAR(34)) &IF(M12="","",","&CHAR(34)&"explain"&CHAR(34)&":"&CHAR(34)&M12&CHAR(34)) &IF(N12="","",","&CHAR(34)&"explainImg"&CHAR(34)&":"&CHAR(34)&N12&CHAR(34)) &IF(O12="","",","&CHAR(34)&"shuffle"&CHAR(34)&":"&CHAR(34)&"false"&CHAR(34))&CHAR(125)&",") | R12: =CHAR(S12) -> _x0010_ | S12: =S11+1 -> 16
A13: 3 | B13: Là khoảng trống có kích thước giới hạn về chiều cao của cầu, bến phà, hầm trên đường bộ để các xe đi qua được an toàn. | C13: =IFERROR(COUNTIFS($A$1:A13,"Câu "&"*")-MID(A13,5,FIND(".",A13,1)-5),0) -> 0 | D13: =IF(LEFT(A13,3)="Câu",VALUE(MID(A13,5,FIND(".",A13,1)-5)),"") | E13: =SUBSTITUTE(IF(LEFT(A13,3)="Câu",MID(A13,FIND(".",A13,1)+2,LEN(A13)),""),CHAR(34),CHAR(92)&CHAR(34)) | G13: =SUBSTITUTE(B14,CHAR(34),CHAR(92)&CHAR(34)) | H13: =SUBSTITUTE(B15,CHAR(34),CHAR(92)&CHAR(34)) -> Để phân chia các làn đường dành cho xe cơ giới và xe thô sơ trên đường cao tốc. | I13: =SUBSTITUTE(IF(LEFT(A16,3)="Câu","",B16),CHAR(34),CHAR(92)&CHAR(34)) -> Để phân chia phần đường xe chạy thành hai chiều riêng biệt hoặc để phân chia phần đường dành cho xe cơ giới và xe thô sơ hoặc của nhiều loại xe khác nhau trên cùng một chiều đường. | J13: =SUBSTITUTE(IF(OR(LEFT(A17,3)="Câu",I13=""),"",IF(B17=0,"",B17)),CHAR(34),CHAR(92)&CHAR(34)) -> Để phân tách phần đường xe chạy và hành lang an toàn giao thông. | K13: =SUBSTITUTE(SUBSTITUTE(SUBSTITUTE(SUBSTITUTE(IFERROR(VLOOKUP("Câu "&D13&".",dapan!$E:$J,6,0),""),"1","A"),"2","B"),"3","C"),"4","D") | P13: =D13 | Q13: =IF(D13="","",CHAR(123)&CHAR(34)&"num"&CHAR(34)&":"&P13&","&CHAR(34)&"id"&CHAR(34)&":"&D13&"," &CHAR(34)&"q"&CHAR(34)&":"&CHAR(34)&E13&CHAR(34)&"," &IF(F13="","",CHAR(34)&"img"&CHAR(34)&":"&CHAR(34)&F13&CHAR(34)&",") &CHAR(34)&"opts"&CHAR(34)&":"&CHAR(123)&CHAR(34)&"A"&CHAR(34)&":"&CHAR(34)&G13&CHAR(34)&","&CHAR(34)&"B"&CHAR(34)&":"&CHAR(34)&H13&CHAR(34) &IF(I13="","",","&CHAR(34)&"C"&CHAR(34)&":"&CHAR(34)&I13&CHAR(34))&IF(J13="","",","&CHAR(34)&"D"&CHAR(34)&":"&CHAR(34)&J13&CHAR(34))&CHAR(125)&"," &CHAR(34)&"answer"&CHAR(34)&":"&CHAR(34)&K13&CHAR(34) &IF(L13="","",","&CHAR(34)&"danger"&CHAR(34)&":"&CHAR(34)&"true"&CHAR(34)) &IF(M13="","",","&CHAR(34)&"explain"&CHAR(34)&":"&CHAR(34)&M13&CHAR(34)) &IF(N13="","",","&CHAR(34)&"explainImg"&CHAR(34)&":"&CHAR(34)&N13&CHAR(34)) &IF(O13="","",","&CHAR(34)&"shuffle"&CHAR(34)&":"&CHAR(34)&"false"&CHAR(34))&CHAR(125)&",") | R13: =CHAR(S13) -> _x0011_ | S13: =S12+1 -> 17
A14: Câu 4. Dải phân cách được lắp đặt để làm gì? | C14: =IFERROR(COUNTIFS($A$1:A14,"Câu "&"*")-MID(A14,5,FIND(".",A14,1)-5),0) -> 0 | D14: =IF(LEFT(A14,3)="Câu",VALUE(MID(A14,5,FIND(".",A14,1)-5)),"") -> 4 | E14: =SUBSTITUTE(IF(LEFT(A14,3)="Câu",MID(A14,FIND(".",A14,1)+2,LEN(A14)),""),CHAR(34),CHAR(92)&CHAR(34)) -> Dải phân cách được lắp đặt để làm gì? | G14: =SUBSTITUTE(B15,CHAR(34),CHAR(92)&CHAR(34)) -> Để phân chia các làn đường dành cho xe cơ giới và xe thô sơ trên đường cao tốc. | H14: =SUBSTITUTE(B16,CHAR(34),CHAR(92)&CHAR(34)) -> Để phân chia phần đường xe chạy thành hai chiều riêng biệt hoặc để phân chia phần đường dành cho xe cơ giới và xe thô sơ hoặc của nhiều loại xe khác nhau trên cùng một chiều đường. | I14: =SUBSTITUTE(IF(LEFT(A17,3)="Câu","",B17),CHAR(34),CHAR(92)&CHAR(34)) -> Để phân tách phần đường xe chạy và hành lang an toàn giao thông. | J14: =SUBSTITUTE(IF(OR(LEFT(A18,3)="Câu",I14=""),"",IF(B18=0,"",B18)),CHAR(34),CHAR(92)&CHAR(34)) | K14: =SUBSTITUTE(SUBSTITUTE(SUBSTITUTE(SUBSTITUTE(IFERROR(VLOOKUP("Câu "&D14&".",dapan!$E:$J,6,0),""),"1","A"),"2","B"),"3","C"),"4","D") -> B | P14: =D14 -> 4 | Q14: =IF(D14="","",CHAR(123)&CHAR(34)&"num"&CHAR(34)&":"&P14&","&CHAR(34)&"id"&CHAR(34)&":"&D14&"," &CHAR(34)&"q"&CHAR(34)&":"&CHAR(34)&E14&CHAR(34)&"," &IF(F14="","",CHAR(34)&"img"&CHAR(34)&":"&CHAR(34)&F14&CHAR(34)&",") &CHAR(34)&"opts"&CHAR(34)&":"&CHAR(123)&CHAR(34)&"A"&CHAR(34)&":"&CHAR(34)&G14&CHAR(34)&","&CHAR(34)&"B"&CHAR(34)&":"&CHAR(34)&H14&CHAR(34) &IF(I14="","",","&CHAR(34)&"C"&CHAR(34)&":"&CHAR(34)&I14&CHAR(34))&IF(J14="","",","&CHAR(34)&"D"&CHAR(34)&":"&CHAR(34)&J14&CHAR(34))&CHAR(125)&"," &CHAR(34)&"answer"&CHAR(34)&":"&CHAR(34)&K14&CHAR(34) &IF(L14="","",","&CHAR(34)&"danger"&CHAR(34)&":"&CHAR(34)&"true"&CHAR(34)) &IF(M14="","",","&CHAR(34)&"explain"&CHAR(34)&":"&CHAR(34)&M14&CHAR(34)) &IF(N14="","",","&CHAR(34)&"explainImg"&CHAR(34)&":"&CHAR(34)&N14&CHAR(34)) &IF(O14="","",","&CHAR(34)&"shuffle"&CHAR(34)&":"&CHAR(34)&"false"&CHAR(34))&CHAR(125)&",") -> {"num":4,"id":4,"q":"Dải phân cách được lắp đặt để làm gì?","opts":{"A":"Để phân chia các làn đường dành cho xe cơ giới và xe thô sơ trên đường cao tốc.","B":"Để phân chia phần đường xe chạy thành hai chiều riêng biệt hoặc để phân chia phần đường dành cho xe cơ giới và xe thô sơ hoặc của nhiều loại xe khác nhau trên cùng một chiều đường.","C":"Để phân tách phần đường xe chạy và hành lang an toàn giao thông."},"answer":"B"}, | R14: =CHAR(S14) -> _x0012_ | S14: =S13+1 -> 18
A15: 1 | B15: Để phân chia các làn đường dành cho xe cơ giới và xe thô sơ trên đường cao tốc. | C15: =IFERROR(COUNTIFS($A$1:A15,"Câu "&"*")-MID(A15,5,FIND(".",A15,1)-5),0) -> 0 | D15: =IF(LEFT(A15,3)="Câu",VALUE(MID(A15,5,FIND(".",A15,1)-5)),"") | E15: =SUBSTITUTE(IF(LEFT(A15,3)="Câu",MID(A15,FIND(".",A15,1)+2,LEN(A15)),""),CHAR(34),CHAR(92)&CHAR(34)) | G15: =SUBSTITUTE(B16,CHAR(34),CHAR(92)&CHAR(34)) -> Để phân chia phần đường xe chạy thành hai chiều riêng biệt hoặc để phân chia phần đường dành cho xe cơ giới và xe thô sơ hoặc của nhiều loại xe khác nhau trên cùng một chiều đường. | H15: =SUBSTITUTE(B17,CHAR(34),CHAR(92)&CHAR(34)) -> Để phân tách phần đường xe chạy và hành lang an toàn giao thông. | I15: =SUBSTITUTE(IF(LEFT(A18,3)="Câu","",B18),CHAR(34),CHAR(92)&CHAR(34)) | J15: =SUBSTITUTE(IF(OR(LEFT(A19,3)="Câu",I15=""),"",IF(B19=0,"",B19)),CHAR(34),CHAR(92)&CHAR(34)) | K15: =SUBSTITUTE(SUBSTITUTE(SUBSTITUTE(SUBSTITUTE(IFERROR(VLOOKUP("Câu "&D15&".",dapan!$E:$J,6,0),""),"1","A"),"2","B"),"3","C"),"4","D") | P15: =D15 | Q15: =IF(D15="","",CHAR(123)&CHAR(34)&"num"&CHAR(34)&":"&P15&","&CHAR(34)&"id"&CHAR(34)&":"&D15&"," &CHAR(34)&"q"&CHAR(34)&":"&CHAR(34)&E15&CHAR(34)&"," &IF(F15="","",CHAR(34)&"img"&CHAR(34)&":"&CHAR(34)&F15&CHAR(34)&",") &CHAR(34)&"opts"&CHAR(34)&":"&CHAR(123)&CHAR(34)&"A"&CHAR(34)&":"&CHAR(34)&G15&CHAR(34)&","&CHAR(34)&"B"&CHAR(34)&":"&CHAR(34)&H15&CHAR(34) &IF(I15="","",","&CHAR(34)&"C"&CHAR(34)&":"&CHAR(34)&I15&CHAR(34))&IF(J15="","",","&CHAR(34)&"D"&CHAR(34)&":"&CHAR(34)&J15&CHAR(34))&CHAR(125)&"," &CHAR(34)&"answer"&CHAR(34)&":"&CHAR(34)&K15&CHAR(34) &IF(L15="","",","&CHAR(34)&"danger"&CHAR(34)&":"&CHAR(34)&"true"&CHAR(34)) &IF(M15="","",","&CHAR(34)&"explain"&CHAR(34)&":"&CHAR(34)&M15&CHAR(34)) &IF(N15="","",","&CHAR(34)&"explainImg"&CHAR(34)&":"&CHAR(34)&N15&CHAR(34)) &IF(O15="","",","&CHAR(34)&"shuffle"&CHAR(34)&":"&CHAR(34)&"false"&CHAR(34))&CHAR(125)&",") | R15: =CHAR(S15) -> _x0013_ | S15: =S14+1 -> 19
A16: 2 | B16: Để phân chia phần đường xe chạy thành hai chiều riêng biệt hoặc để phân chia phần đường dành cho xe cơ giới và xe thô sơ hoặc của nhiều loại xe khác nhau trên cùng một chiều đường. | C16: =IFERROR(COUNTIFS($A$1:A16,"Câu "&"*")-MID(A16,5,FIND(".",A16,1)-5),0) -> 0 | D16: =IF(LEFT(A16,3)="Câu",VALUE(MID(A16,5,FIND(".",A16,1)-5)),"") | E16: =SUBSTITUTE(IF(LEFT(A16,3)="Câu",MID(A16,FIND(".",A16,1)+2,LEN(A16)),""),CHAR(34),CHAR(92)&CHAR(34)) | G16: =SUBSTITUTE(B17,CHAR(34),CHAR(92)&CHAR(34)) -> Để phân tách phần đường xe chạy và hành lang an toàn giao thông. | H16: =SUBSTITUTE(B18,CHAR(34),CHAR(92)&CHAR(34)) | I16: =SUBSTITUTE(IF(LEFT(A19,3)="Câu","",B19),CHAR(34),CHAR(92)&CHAR(34)) -> Là báo hiệu đường bộ để hỗ trợ cảnh báo nguy hiểm cho người tham gia giao thông đường bộ. | J16: =SUBSTITUTE(IF(OR(LEFT(A20,3)="Câu",I16=""),"",IF(B20=0,"",B20)),CHAR(34),CHAR(92)&CHAR(34)) -> Là vạch chỉ sự phân chia làn đường, vị trí hoặc hướng đi, vị trí dừng lại. | K16: =SUBSTITUTE(SUBSTITUTE(SUBSTITUTE(SUBSTITUTE(IFERROR(VLOOKUP("Câu "&D16&".",dapan!$E:$J,6,0),""),"1","A"),"2","B"),"3","C"),"4","D") | P16: =D16 | Q16: =IF(D16="","",CHAR(123)&CHAR(34)&"num"&CHAR(34)&":"&P16&","&CHAR(34)&"id"&CHAR(34)&":"&D16&"," &CHAR(34)&"q"&CHAR(34)&":"&CHAR(34)&E16&CHAR(34)&"," &IF(F16="","",CHAR(34)&"img"&CHAR(34)&":"&CHAR(34)&F16&CHAR(34)&",") &CHAR(34)&"opts"&CHAR(34)&":"&CHAR(123)&CHAR(34)&"A"&CHAR(34)&":"&CHAR(34)&G16&CHAR(34)&","&CHAR(34)&"B"&CHAR(34)&":"&CHAR(34)&H16&CHAR(34) &IF(I16="","",","&CHAR(34)&"C"&CHAR(34)&":"&CHAR(34)&I16&CHAR(34))&IF(J16="","",","&CHAR(34)&"D"&CHAR(34)&":"&CHAR(34)&J16&CHAR(34))&CHAR(125)&"," &CHAR(34)&"answer"&CHAR(34)&":"&CHAR(34)&K16&CHAR(34) &IF(L16="","",","&CHAR(34)&"danger"&CHAR(34)&":"&CHAR(34)&"true"&CHAR(34)) &IF(M16="","",","&CHAR(34)&"explain"&CHAR(34)&":"&CHAR(34)&M16&CHAR(34)) &IF(N16="","",","&CHAR(34)&"explainImg"&CHAR(34)&":"&CHAR(34)&N16&CHAR(34)) &IF(O16="","",","&CHAR(34)&"shuffle"&CHAR(34)&":"&CHAR(34)&"false"&CHAR(34))&CHAR(125)&",") | R16: =CHAR(S16) -> _x0014_ | S16: =S15+1 -> 20
A17: 3 | B17: Để phân tách phần đường xe chạy và hành lang an toàn giao thông. | C17: =IFERROR(COUNTIFS($A$1:A17,"Câu "&"*")-MID(A17,5,FIND(".",A17,1)-5),0) -> 0 | D17: =IF(LEFT(A17,3)="Câu",VALUE(MID(A17,5,FIND(".",A17,1)-5)),"") | E17: =SUBSTITUTE(IF(LEFT(A17,3)="Câu",MID(A17,FIND(".",A17,1)+2,LEN(A17)),""),CHAR(34),CHAR(92)&CHAR(34)) | G17: =SUBSTITUTE(B18,CHAR(34),CHAR(92)&CHAR(34)) | H17: =SUBSTITUTE(B19,CHAR(34),CHAR(92)&CHAR(34)) -> Là báo hiệu đường bộ để hỗ trợ cảnh báo nguy hiểm cho người tham gia giao thông đường bộ. | I17: =SUBSTITUTE(IF(LEFT(A20,3)="Câu","",B20),CHAR(34),CHAR(92)&CHAR(34)) -> Là vạch chỉ sự phân chia làn đường, vị trí hoặc hướng đi, vị trí dừng lại. | J17: =SUBSTITUTE(IF(OR(LEFT(A21,3)="Câu",I17=""),"",IF(B21=0,"",B21)),CHAR(34),CHAR(92)&CHAR(34)) -> Là báo hiệu cho người tham gia giao thông đường bộ về các thông tin của đường bộ. | K17: =SUBSTITUTE(SUBSTITUTE(SUBSTITUTE(SUBSTITUTE(IFERROR(VLOOKUP("Câu "&D17&".",dapan!$E:$J,6,0),""),"1","A"),"2","B"),"3","C"),"4","D") | P17: =D17 | Q17: =IF(D17="","",CHAR(123)&CHAR(34)&"num"&CHAR(34)&":"&P17&","&CHAR(34)&"id"&CHAR(34)&":"&D17&"," &CHAR(34)&"q"&CHAR(34)&":"&CHAR(34)&E17&CHAR(34)&"," &IF(F17="","",CHAR(34)&"img"&CHAR(34)&":"&CHAR(34)&F17&CHAR(34)&",") &CHAR(34)&"opts"&CHAR(34)&":"&CHAR(123)&CHAR(34)&"A"&CHAR(34)&":"&CHAR(34)&G17&CHAR(34)&","&CHAR(34)&"B"&CHAR(34)&":"&CHAR(34)&H17&CHAR(34) &IF(I17="","",","&CHAR(34)&"C"&CHAR(34)&":"&CHAR(34)&I17&CHAR(34))&IF(J17="","",","&CHAR(34)&"D"&CHAR(34)&":"&CHAR(34)&J17&CHAR(34))&CHAR(125)&"," &CHAR(34)&"answer"&CHAR(34)&":"&CHAR(34)&K17&CHAR(34) &IF(L17="","",","&CHAR(34)&"danger"&CHAR(34)&":"&CHAR(34)&"true"&CHAR(34)) &IF(M17="","",","&CHAR(34)&"explain"&CHAR(34)&":"&CHAR(34)&M17&CHAR(34)) &IF(N17="","",","&CHAR(34)&"explainImg"&CHAR(34)&":"&CHAR(34)&N17&CHAR(34)) &IF(O17="","",","&CHAR(34)&"shuffle"&CHAR(34)&":"&CHAR(34)&"false"&CHAR(34))&CHAR(125)&",") | R17: =CHAR(S17) -> _x0015_ | S17: =S16+1 -> 21
A18: Câu 5. Vạch kẻ đường là gì? | C18: =IFERROR(COUNTIFS($A$1:A18,"Câu "&"*")-MID(A18,5,FIND(".",A18,1)-5),0) -> 0 | D18: =IF(LEFT(A18,3)="Câu",VALUE(MID(A18,5,FIND(".",A18,1)-5)),"") -> 5 | E18: =SUBSTITUTE(IF(LEFT(A18,3)="Câu",MID(A18,FIND(".",A18,1)+2,LEN(A18)),""),CHAR(34),CHAR(92)&CHAR(34)) -> Vạch kẻ đường là gì? | G18: =SUBSTITUTE(B19,CHAR(34),CHAR(92)&CHAR(34)) -> Là báo hiệu đường bộ để hỗ trợ cảnh báo nguy hiểm cho người tham gia giao thông đường bộ. | H18: =SUBSTITUTE(B20,CHAR(34),CHAR(92)&CHAR(34)) -> Là vạch chỉ sự phân chia làn đường, vị trí hoặc hướng đi, vị trí dừng lại. | I18: =SUBSTITUTE(IF(LEFT(A21,3)="Câu","",B21),CHAR(34),CHAR(92)&CHAR(34)) -> Là báo hiệu cho người tham gia giao thông đường bộ về các thông tin của đường bộ. | J18: =SUBSTITUTE(IF(OR(LEFT(A22,3)="Câu",I18=""),"",IF(B22=0,"",B22)),CHAR(34),CHAR(92)&CHAR(34)) -> Cả ba ý trên. | K18: =SUBSTITUTE(SUBSTITUTE(SUBSTITUTE(SUBSTITUTE(IFERROR(VLOOKUP("Câu "&D18&".",dapan!$E:$J,6,0),""),"1","A"),"2","B"),"3","C"),"4","D") -> B | P18: =D18 -> 5 | Q18: =IF(D18="","",CHAR(123)&CHAR(34)&"num"&CHAR(34)&":"&P18&","&CHAR(34)&"id"&CHAR(34)&":"&D18&"," &CHAR(34)&"q"&CHAR(34)&":"&CHAR(34)&E18&CHAR(34)&"," &IF(F18="","",CHAR(34)&"img"&CHAR(34)&":"&CHAR(34)&F18&CHAR(34)&",") &CHAR(34)&"opts"&CHAR(34)&":"&CHAR(123)&CHAR(34)&"A"&CHAR(34)&":"&CHAR(34)&G18&CHAR(34)&","&CHAR(34)&"B"&CHAR(34)&":"&CHAR(34)&H18&CHAR(34) &IF(I18="","",","&CHAR(34)&"C"&CHAR(34)&":"&CHAR(34)&I18&CHAR(34))&IF(J18="","",","&CHAR(34)&"D"&CHAR(34)&":"&CHAR(34)&J18&CHAR(34))&CHAR(125)&"," &CHAR(34)&"answer"&CHAR(34)&":"&CHAR(34)&K18&CHAR(34) &IF(L18="","",","&CHAR(34)&"danger"&CHAR(34)&":"&CHAR(34)&"true"&CHAR(34)) &IF(M18="","",","&CHAR(34)&"explain"&CHAR(34)&":"&CHAR(34)&M18&CHAR(34)) &IF(N18="","",","&CHAR(34)&"explainImg"&CHAR(34)&":"&CHAR(34)&N18&CHAR(34)) &IF(O18="","",","&CHAR(34)&"shuffle"&CHAR(34)&":"&CHAR(34)&"false"&CHAR(34))&CHAR(125)&",") -> {"num":5,"id":5,"q":"Vạch kẻ đường là gì?","opts":{"A":"Là báo hiệu đường bộ để hỗ trợ cảnh báo nguy hiểm cho người tham gia giao thông đường bộ.","B":"Là vạch chỉ sự phân chia làn đường, vị trí hoặc hướng đi, vị trí dừng lại.","C":"Là báo hiệu cho người tham gia giao thông đường bộ về các thông tin của đường bộ.","D":"Cả ba ý trên."},"answer":"B"}, | R18: =CHAR(S18) -> _x0016_ | S18: =S17+1 -> 22
A19: 1 | B19: Là báo hiệu đường bộ để hỗ trợ cảnh báo nguy hiểm cho người tham gia giao thông đường bộ. | C19: =IFERROR(COUNTIFS($A$1:A19,"Câu "&"*")-MID(A19,5,FIND(".",A19,1)-5),0) -> 0 | D19: =IF(LEFT(A19,3)="Câu",VALUE(MID(A19,5,FIND(".",A19,1)-5)),"") | E19: =SUBSTITUTE(IF(LEFT(A19,3)="Câu",MID(A19,FIND(".",A19,1)+2,LEN(A19)),""),CHAR(34),CHAR(92)&CHAR(34)) | G19: =SUBSTITUTE(B20,CHAR(34),CHAR(92)&CHAR(34)) -> Là vạch chỉ sự phân chia làn đường, vị trí hoặc hướng đi, vị trí dừng lại. | H19: =SUBSTITUTE(B21,CHAR(34),CHAR(92)&CHAR(34)) -> Là báo hiệu cho người tham gia giao thông đường bộ về các thông tin của đường bộ. | I19: =SUBSTITUTE(IF(LEFT(A22,3)="Câu","",B22),CHAR(34),CHAR(92)&CHAR(34)) -> Cả ba ý trên. | J19: =SUBSTITUTE(IF(OR(LEFT(A23,3)="Câu",I19=""),"",IF(B23=0,"",B23)),CHAR(34),CHAR(92)&CHAR(34)) | K19: =SUBSTITUTE(SUBSTITUTE(SUBSTITUTE(SUBSTITUTE(IFERROR(VLOOKUP("Câu "&D19&".",dapan!$E:$J,6,0),""),"1","A"),"2","B"),"3","C"),"4","D") | P19: =D19 | Q19: =IF(D19="","",CHAR(123)&CHAR(34)&"num"&CHAR(34)&":"&P19&","&CHAR(34)&"id"&CHAR(34)&":"&D19&"," &CHAR(34)&"q"&CHAR(34)&":"&CHAR(34)&E19&CHAR(34)&"," &IF(F19="","",CHAR(34)&"img"&CHAR(34)&":"&CHAR(34)&F19&CHAR(34)&",") &CHAR(34)&"opts"&CHAR(34)&":"&CHAR(123)&CHAR(34)&"A"&CHAR(34)&":"&CHAR(34)&G19&CHAR(34)&","&CHAR(34)&"B"&CHAR(34)&":"&CHAR(34)&H19&CHAR(34) &IF(I19="","",","&CHAR(34)&"C"&CHAR(34)&":"&CHAR(34)&I19&CHAR(34))&IF(J19="","",","&CHAR(34)&"D"&CHAR(34)&":"&CHAR(34)&J19&CHAR(34))&CHAR(125)&"," &CHAR(34)&"answer"&CHAR(34)&":"&CHAR(34)&K19&CHAR(34) &IF(L19="","",","&CHAR(34)&"danger"&CHAR(34)&":"&CHAR(34)&"true"&CHAR(34)) &IF(M19="","",","&CHAR(34)&"explain"&CHAR(34)&":"&CHAR(34)&M19&CHAR(34)) &IF(N19="","",","&CHAR(34)&"explainImg"&CHAR(34)&":"&CHAR(34)&N19&CHAR(34)) &IF(O19="","",","&CHAR(34)&"shuffle"&CHAR(34)&":"&CHAR(34)&"false"&CHAR(34))&CHAR(125)&",") | R19: =CHAR(S19) -> _x0017_ | S19: =S18+1 -> 23
A20: 2 | B20: Là vạch chỉ sự phân chia làn đường, vị trí hoặc hướng đi, vị trí dừng lại. | C20: =IFERROR(COUNTIFS($A$1:A20,"Câu "&"*")-MID(A20,5,FIND(".",A20,1)-5),0) -> 0 | D20: =IF(LEFT(A20,3)="Câu",VALUE(MID(A20,5,FIND(".",A20,1)-5)),"") | E20: =SUBSTITUTE(IF(LEFT(A20,3)="Câu",MID(A20,FIND(".",A20,1)+2,LEN(A20)),""),CHAR(34),CHAR(92)&CHAR(34)) | G20: =SUBSTITUTE(B21,CHAR(34),CHAR(92)&CHAR(34)) -> Là báo hiệu cho người tham gia giao thông đường bộ về các thông tin của đường bộ. | H20: =SUBSTITUTE(B22,CHAR(34),CHAR(92)&CHAR(34)) -> Cả ba ý trên. | I20: =SUBSTITUTE(IF(LEFT(A23,3)="Câu","",B23),CHAR(34),CHAR(92)&CHAR(34)) | J20: =SUBSTITUTE(IF(OR(LEFT(A24,3)="Câu",I20=""),"",IF(B24=0,"",B24)),CHAR(34),CHAR(92)&CHAR(34)) | K20: =SUBSTITUTE(SUBSTITUTE(SUBSTITUTE(SUBSTITUTE(IFERROR(VLOOKUP("Câu "&D20&".",dapan!$E:$J,6,0),""),"1","A"),"2","B"),"3","C"),"4","D") | P20: =D20 | Q20: =IF(D20="","",CHAR(123)&CHAR(34)&"num"&CHAR(34)&":"&P20&","&CHAR(34)&"id"&CHAR(34)&":"&D20&"," &CHAR(34)&"q"&CHAR(34)&":"&CHAR(34)&E20&CHAR(34)&"," &IF(F20="","",CHAR(34)&"img"&CHAR(34)&":"&CHAR(34)&F20&CHAR(34)&",") &CHAR(34)&"opts"&CHAR(34)&":"&CHAR(123)&CHAR(34)&"A"&CHAR(34)&":"&CHAR(34)&G20&CHAR(34)&","&CHAR(34)&"B"&CHAR(34)&":"&CHAR(34)&H20&CHAR(34) &IF(I20="","",","&CHAR(34)&"C"&CHAR(34)&":"&CHAR(34)&I20&CHAR(34))&IF(J20="","",","&CHAR(34)&"D"&CHAR(34)&":"&CHAR(34)&J20&CHAR(34))&CHAR(125)&"," &CHAR(34)&"answer"&CHAR(34)&":"&CHAR(34)&K20&CHAR(34) &IF(L20="","",","&CHAR(34)&"danger"&CHAR(34)&":"&CHAR(34)&"true"&CHAR(34)) &IF(M20="","",","&CHAR(34)&"explain"&CHAR(34)&":"&CHAR(34)&M20&CHAR(34)) &IF(N20="","",","&CHAR(34)&"explainImg"&CHAR(34)&":"&CHAR(34)&N20&CHAR(34)) &IF(O20="","",","&CHAR(34)&"shuffle"&CHAR(34)&":"&CHAR(34)&"false"&CHAR(34))&CHAR(125)&",") | R20: =CHAR(S20) -> _x0018_ | S20: =S19+1 -> 24
A21: 3 | B21: Là báo hiệu cho người tham gia giao thông đường bộ về các thông tin của đường bộ. | C21: =IFERROR(COUNTIFS($A$1:A21,"Câu "&"*")-MID(A21,5,FIND(".",A21,1)-5),0) -> 0 | D21: =IF(LEFT(A21,3)="Câu",VALUE(MID(A21,5,FIND(".",A21,1)-5)),"") | E21: =SUBSTITUTE(IF(LEFT(A21,3)="Câu",MID(A21,FIND(".",A21,1)+2,LEN(A21)),""),CHAR(34),CHAR(92)&CHAR(34)) | G21: =SUBSTITUTE(B22,CHAR(34),CHAR(92)&CHAR(34)) -> Cả ba ý trên. | H21: =SUBSTITUTE(B23,CHAR(34),CHAR(92)&CHAR(34)) | I21: =SUBSTITUTE(IF(LEFT(A24,3)="Câu","",B24),CHAR(34),CHAR(92)&CHAR(34)) -> Là người điều khiển xe cơ giới, người điều khiển xe thô sơ, người điều khiển xe máy chuyên dùng. | J21: =SUBSTITUTE(IF(OR(LEFT(A25,3)="Câu",I21=""),"",IF(B25=0,"",B25)),CHAR(34),CHAR(92)&CHAR(34)) -> Là người được giao nhiệm vụ hướng dẫn giao thông trên đường bộ. | K21: =SUBSTITUTE(SUBSTITUTE(SUBSTITUTE(SUBSTITUTE(IFERROR(VLOOKUP("Câu "&D21&".",dapan!$E:$J,6,0),""),"1","A"),"2","B"),"3","C"),"4","D") | P21: =D21 | Q21: =IF(D21="","",CHAR(123)&CHAR(34)&"num"&CHAR(34)&":"&P21&","&CHAR(34)&"id"&CHAR(34)&":"&D21&"," &CHAR(34)&"q"&CHAR(34)&":"&CHAR(34)&E21&CHAR(34)&"," &IF(F21="","",CHAR(34)&"img"&CHAR(34)&":"&CHAR(34)&F21&CHAR(34)&",") &CHAR(34)&"opts"&CHAR(34)&":"&CHAR(123)&CHAR(34)&"A"&CHAR(34)&":"&CHAR(34)&G21&CHAR(34)&","&CHAR(34)&"B"&CHAR(34)&":"&CHAR(34)&H21&CHAR(34) &IF(I21="","",","&CHAR(34)&"C"&CHAR(34)&":"&CHAR(34)&I21&CHAR(34))&IF(J21="","",","&CHAR(34)&"D"&CHAR(34)&":"&CHAR(34)&J21&CHAR(34))&CHAR(125)&"," &CHAR(34)&"answer"&CHAR(34)&":"&CHAR(34)&K21&CHAR(34) &IF(L21="","",","&CHAR(34)&"danger"&CHAR(34)&":"&CHAR(34)&"true"&CHAR(34)) &IF(M21="","",","&CHAR(34)&"explain"&CHAR(34)&":"&CHAR(34)&M21&CHAR(34)) &IF(N21="","",","&CHAR(34)&"explainImg"&CHAR(34)&":"&CHAR(34)&N21&CHAR(34)) &IF(O21="","",","&CHAR(34)&"shuffle"&CHAR(34)&":"&CHAR(34)&"false"&CHAR(34))&CHAR(125)&",") | R21: =CHAR(S21) -> _x0019_ | S21: =S20+1 -> 25
A22: 4 | B22: Cả ba ý trên. | C22: =IFERROR(COUNTIFS($A$1:A22,"Câu "&"*")-MID(A22,5,FIND(".",A22,1)-5),0) -> 0 | D22: =IF(LEFT(A22,3)="Câu",VALUE(MID(A22,5,FIND(".",A22,1)-5)),"") | E22: =SUBSTITUTE(IF(LEFT(A22,3)="Câu",MID(A22,FIND(".",A22,1)+2,LEN(A22)),""),CHAR(34),CHAR(92)&CHAR(34)) | G22: =SUBSTITUTE(B23,CHAR(34),CHAR(92)&CHAR(34)) | H22: =SUBSTITUTE(B24,CHAR(34),CHAR(92)&CHAR(34)) -> Là người điều khiển xe cơ giới, người điều khiển xe thô sơ, người điều khiển xe máy chuyên dùng. | I22: =SUBSTITUTE(IF(LEFT(A25,3)="Câu","",B25),CHAR(34),CHAR(92)&CHAR(34)) -> Là người được giao nhiệm vụ hướng dẫn giao thông trên đường bộ. | J22: =SUBSTITUTE(IF(OR(LEFT(A26,3)="Câu",I22=""),"",IF(B26=0,"",B26)),CHAR(34),CHAR(92)&CHAR(34)) -> Cả hai ý trên. | K22: =SUBSTITUTE(SUBSTITUTE(SUBSTITUTE(SUBSTITUTE(IFERROR(VLOOKUP("Câu "&D22&".",dapan!$E:$J,6,0),""),"1","A"),"2","B"),"3","C"),"4","D") | P22: =D22 | Q22: =IF(D22="","",CHAR(123)&CHAR(34)&"num"&CHAR(34)&":"&P22&","&CHAR(34)&"id"&CHAR(34)&":"&D22&"," &CHAR(34)&"q"&CHAR(34)&":"&CHAR(34)&E22&CHAR(34)&"," &IF(F22="","",CHAR(34)&"img"&CHAR(34)&":"&CHAR(34)&F22&CHAR(34)&",") &CHAR(34)&"opts"&CHAR(34)&":"&CHAR(123)&CHAR(34)&"A"&CHAR(34)&":"&CHAR(34)&G22&CHAR(34)&","&CHAR(34)&"B"&CHAR(34)&":"&CHAR(34)&H22&CHAR(34) &IF(I22="","",","&CHAR(34)&"C"&CHAR(34)&":"&CHAR(34)&I22&CHAR(34))&IF(J22="","",","&CHAR(34)&"D"&CHAR(34)&":"&CHAR(34)&J22&CHAR(34))&CHAR(125)&"," &CHAR(34)&"answer"&CHAR(34)&":"&CHAR(34)&K22&CHAR(34) &IF(L22="","",","&CHAR(34)&"danger"&CHAR(34)&":"&CHAR(34)&"true"&CHAR(34)) &IF(M22="","",","&CHAR(34)&"explain"&CHAR(34)&":"&CHAR(34)&M22&CHAR(34)) &IF(N22="","",","&CHAR(34)&"explainImg"&CHAR(34)&":"&CHAR(34)&N22&CHAR(34)) &IF(O22="","",","&CHAR(34)&"shuffle"&CHAR(34)&":"&CHAR(34)&"false"&CHAR(34))&CHAR(125)&",") | R22: =CHAR(S22) -> _x001A_ | S22: =S21+1 -> 26
A23: Câu 6. Người điều khiển phương tiện tham gia giao thông đường bộ được hiểu như thế nào là đúng? | C23: =IFERROR(COUNTIFS($A$1:A23,"Câu "&"*")-MID(A23,5,FIND(".",A23,1)-5),0) -> 0 | D23: =IF(LEFT(A23,3)="Câu",VALUE(MID(A23,5,FIND(".",A23,1)-5)),"") -> 6 | E23: =SUBSTITUTE(IF(LEFT(A23,3)="Câu",MID(A23,FIND(".",A23,1)+2,LEN(A23)),""),CHAR(34),CHAR(92)&CHAR(34)) -> Người điều khiển phương tiện tham gia giao thông đường bộ được hiểu như thế nào là đúng? | G23: =SUBSTITUTE(B24,CHAR(34),CHAR(92)&CHAR(34)) -> Là người điều khiển xe cơ giới, người điều khiển xe thô sơ, người điều khiển xe máy chuyên dùng. | H23: =SUBSTITUTE(B25,CHAR(34),CHAR(92)&CHAR(34)) -> Là người được giao nhiệm vụ hướng dẫn giao thông trên đường bộ. | I23: =SUBSTITUTE(IF(LEFT(A26,3)="Câu","",B26),CHAR(34),CHAR(92)&CHAR(34)) -> Cả hai ý trên. | J23: =SUBSTITUTE(IF(OR(LEFT(A27,3)="Câu",I23=""),"",IF(B27=0,"",B27)),CHAR(34),CHAR(92)&CHAR(34)) | K23: =SUBSTITUTE(SUBSTITUTE(SUBSTITUTE(SUBSTITUTE(IFERROR(VLOOKUP("Câu "&D23&".",dapan!$E:$J,6,0),""),"1","A"),"2","B"),"3","C"),"4","D") -> A | P23: =D23 -> 6 | Q23: =IF(D23="","",CHAR(123)&CHAR(34)&"num"&CHAR(34)&":"&P23&","&CHAR(34)&"id"&CHAR(34)&":"&D23&"," &CHAR(34)&"q"&CHAR(34)&":"&CHAR(34)&E23&CHAR(34)&"," &IF(F23="","",CHAR(34)&"img"&CHAR(34)&":"&CHAR(34)&F23&CHAR(34)&",") &CHAR(34)&"opts"&CHAR(34)&":"&CHAR(123)&CHAR(34)&"A"&CHAR(34)&":"&CHAR(34)&G23&CHAR(34)&","&CHAR(34)&"B"&CHAR(34)&":"&CHAR(34)&H23&CHAR(34) &IF(I23="","",","&CHAR(34)&"C"&CHAR(34)&":"&CHAR(34)&I23&CHAR(34))&IF(J23="","",","&CHAR(34)&"D"&CHAR(34)&":"&CHAR(34)&J23&CHAR(34))&CHAR(125)&"," &CHAR(34)&"answer"&CHAR(34)&":"&CHAR(34)&K23&CHAR(34) &IF(L23="","",","&CHAR(34)&"danger"&CHAR(34)&":"&CHAR(34)&"true"&CHAR(34)) &IF(M23="","",","&CHAR(34)&"explain"&CHAR(34)&":"&CHAR(34)&M23&CHAR(34)) &IF(N23="","",","&CHAR(34)&"explainImg"&CHAR(34)&":"&CHAR(34)&N23&CHAR(34)) &IF(O23="","",","&CHAR(34)&"shuffle"&CHAR(34)&":"&CHAR(34)&"false"&CHAR(34))&CHAR(125)&",") -> {"num":6,"id":6,"q":"Người điều khiển phương tiện tham gia giao thông đường bộ được hiểu như thế nào là đúng?","opts":{"A":"Là người điều khiển xe cơ giới, người điều khiển xe thô sơ, người điều khiển xe máy chuyên dùng.","B":"Là người được giao nhiệm vụ hướng dẫn giao thông trên đường bộ.","C":"Cả hai ý trên."},"answer":"A"}, | R23: =CHAR(S23) -> _x001B_ | S23: =S22+1 -> 27
A24: 1 | B24: Là người điều khiển xe cơ giới, người điều khiển xe thô sơ, người điều khiển xe máy chuyên dùng. | C24: =IFERROR(COUNTIFS($A$1:A24,"Câu "&"*")-MID(A24,5,FIND(".",A24,1)-5),0) -> 0 | D24: =IF(LEFT(A24,3)="Câu",VALUE(MID(A24,5,FIND(".",A24,1)-5)),"") | E24: =SUBSTITUTE(IF(LEFT(A24,3)="Câu",MID(A24,FIND(".",A24,1)+2,LEN(A24)),""),CHAR(34),CHAR(92)&CHAR(34)) | G24: =SUBSTITUTE(B25,CHAR(34),CHAR(92)&CHAR(34)) -> Là người được giao nhiệm vụ hướng dẫn giao thông trên đường bộ. | H24: =SUBSTITUTE(B26,CHAR(34),CHAR(92)&CHAR(34)) -> Cả hai ý trên. | I24: =SUBSTITUTE(IF(LEFT(A27,3)="Câu","",B27),CHAR(34),CHAR(92)&CHAR(34)) | J24: =SUBSTITUTE(IF(OR(LEFT(A28,3)="Câu",I24=""),"",IF(B28=0,"",B28)),CHAR(34),CHAR(92)&CHAR(34)) | K24: =SUBSTITUTE(SUBSTITUTE(SUBSTITUTE(SUBSTITUTE(IFERROR(VLOOKUP("Câu "&D24&".",dapan!$E:$J,6,0),""),"1","A"),"2","B"),"3","C"),"4","D") | P24: =D24 | Q24: =IF(D24="","",CHAR(123)&CHAR(34)&"num"&CHAR(34)&":"&P24&","&CHAR(34)&"id"&CHAR(34)&":"&D24&"," &CHAR(34)&"q"&CHAR(34)&":"&CHAR(34)&E24&CHAR(34)&"," &IF(F24="","",CHAR(34)&"img"&CHAR(34)&":"&CHAR(34)&F24&CHAR(34)&",") &CHAR(34)&"opts"&CHAR(34)&":"&CHAR(123)&CHAR(34)&"A"&CHAR(34)&":"&CHAR(34)&G24&CHAR(34)&","&CHAR(34)&"B"&CHAR(34)&":"&CHAR(34)&H24&CHAR(34) &IF(I24="","",","&CHAR(34)&"C"&CHAR(34)&":"&CHAR(34)&I24&CHAR(34))&IF(J24="","",","&CHAR(34)&"D"&CHAR(34)&":"&CHAR(34)&J24&CHAR(34))&CHAR(125)&"," &CHAR(34)&"answer"&CHAR(34)&":"&CHAR(34)&K24&CHAR(34) &IF(L24="","",","&CHAR(34)&"danger"&CHAR(34)&":"&CHAR(34)&"true"&CHAR(34)) &IF(M24="","",","&CHAR(34)&"explain"&CHAR(34)&":"&CHAR(34)&M24&CHAR(34)) &IF(N24="","",","&CHAR(34)&"explainImg"&CHAR(34)&":"&CHAR(34)&N24&CHAR(34)) &IF(O24="","",","&CHAR(34)&"shuffle"&CHAR(34)&":"&CHAR(34)&"false"&CHAR(34))&CHAR(125)&",") | R24: =CHAR(S24) -> _x001C_ | S24: =S23+1 -> 28
A25: 2 | B25: Là người được giao nhiệm vụ hướng dẫn giao thông trên đường bộ. | C25: =IFERROR(COUNTIFS($A$1:A25,"Câu "&"*")-MID(A25,5,FIND(".",A25,1)-5),0) -> 0 | D25: =IF(LEFT(A25,3)="Câu",VALUE(MID(A25,5,FIND(".",A25,1)-5)),"") | E25: =SUBSTITUTE(IF(LEFT(A25,3)="Câu",MID(A25,FIND(".",A25,1)+2,LEN(A25)),""),CHAR(34),CHAR(92)&CHAR(34)) | G25: =SUBSTITUTE(B26,CHAR(34),CHAR(92)&CHAR(34)) -> Cả hai ý trên. | H25: =SUBSTITUTE(B27,CHAR(34),CHAR(92)&CHAR(34)) | I25: =SUBSTITUTE(IF(LEFT(A28,3)="Câu","",B28),CHAR(34),CHAR(92)&CHAR(34)) -> Là người điều khiển xe cơ giới. | J25: =SUBSTITUTE(IF(OR(LEFT(A29,3)="Câu",I25=""),"",IF(B29=0,"",B29)),CHAR(34),CHAR(92)&CHAR(34)) -> Là người điều khiển xe thô sơ. | K25: =SUBSTITUTE(SUBSTITUTE(SUBSTITUTE(SUBSTITUTE(IFERROR(VLOOKUP("Câu "&D25&".",dapan!$E:$J,6,0),""),"1","A"),"2","B"),"3","C"),"4","D") | P25: =D25 | Q25: =IF(D25="","",CHAR(123)&CHAR(34)&"num"&CHAR(34)&":"&P25&","&CHAR(34)&"id"&CHAR(34)&":"&D25&"," &CHAR(34)&"q"&CHAR(34)&":"&CHAR(34)&E25&CHAR(34)&"," &IF(F25="","",CHAR(34)&"img"&CHAR(34)&":"&CHAR(34)&F25&CHAR(34)&",") &CHAR(34)&"opts"&CHAR(34)&":"&CHAR(123)&CHAR(34)&"A"&CHAR(34)&":"&CHAR(34)&G25&CHAR(34)&","&CHAR(34)&"B"&CHAR(34)&":"&CHAR(34)&H25&CHAR(34) &IF(I25="","",","&CHAR(34)&"C"&CHAR(34)&":"&CHAR(34)&I25&CHAR(34))&IF(J25="","",","&CHAR(34)&"D"&CHAR(34)&":"&CHAR(34)&J25&CHAR(34))&CHAR(125)&"," &CHAR(34)&"answer"&CHAR(34)&":"&CHAR(34)&K25&CHAR(34) &IF(L25="","",","&CHAR(34)&"danger"&CHAR(34)&":"&CHAR(34)&"true"&CHAR(34)) &IF(M25="","",","&CHAR(34)&"explain"&CHAR(34)&":"&CHAR(34)&M25&CHAR(34)) &IF(N25="","",","&CHAR(34)&"explainImg"&CHAR(34)&":"&CHAR(34)&N25&CHAR(34)) &IF(O25="","",","&CHAR(34)&"shuffle"&CHAR(34)&":"&CHAR(34)&"false"&CHAR(34))&CHAR(125)&",") | R25: =CHAR(S25) -> _x001D_ | S25: =S24+1 -> 29
A26: 3 | B26: Cả hai ý trên. | C26: =IFERROR(COUNTIFS($A$1:A26,"Câu "&"*")-MID(A26,5,FIND(".",A26,1)-5),0) -> 0 | D26: =IF(LEFT(A26,3)="Câu",VALUE(MID(A26,5,FIND(".",A26,1)-5)),"") | E26: =SUBSTITUTE(IF(LEFT(A26,3)="Câu",MID(A26,FIND(".",A26,1)+2,LEN(A26)),""),CHAR(34),CHAR(92)&CHAR(34)) | G26: =SUBSTITUTE(B27,CHAR(34),CHAR(92)&CHAR(34)) | H26: =SUBSTITUTE(B28,CHAR(34),CHAR(92)&CHAR(34)) -> Là người điều khiển xe cơ giới. | I26: =SUBSTITUTE(IF(LEFT(A29,3)="Câu","",B29),CHAR(34),CHAR(92)&CHAR(34)) -> Là người điều khiển xe thô sơ. | J26: =SUBSTITUTE(IF(OR(LEFT(A30,3)="Câu",I26=""),"",IF(B30=0,"",B30)),CHAR(34),CHAR(92)&CHAR(34)) -> Là người điều khiển xe máy chuyên dùng. | K26: =SUBSTITUTE(SUBSTITUTE(SUBSTITUTE(SUBSTITUTE(IFERROR(VLOOKUP("Câu "&D26&".",dapan!$E:$J,6,0),""),"1","A"),"2","B"),"3","C"),"4","D") | P26: =D26 | Q26: =IF(D26="","",CHAR(123)&CHAR(34)&"num"&CHAR(34)&":"&P26&","&CHAR(34)&"id"&CHAR(34)&":"&D26&"," &CHAR(34)&"q"&CHAR(34)&":"&CHAR(34)&E26&CHAR(34)&"," &IF(F26="","",CHAR(34)&"img"&CHAR(34)&":"&CHAR(34)&F26&CHAR(34)&",") &CHAR(34)&"opts"&CHAR(34)&":"&CHAR(123)&CHAR(34)&"A"&CHAR(34)&":"&CHAR(34)&G26&CHAR(34)&","&CHAR(34)&"B"&CHAR(34)&":"&CHAR(34)&H26&CHAR(34) &IF(I26="","",","&CHAR(34)&"C"&CHAR(34)&":"&CHAR(34)&I26&CHAR(34))&IF(J26="","",","&CHAR(34)&"D"&CHAR(34)&":"&CHAR(34)&J26&CHAR(34))&CHAR(125)&"," &CHAR(34)&"answer"&CHAR(34)&":"&CHAR(34)&K26&CHAR(34) &IF(L26="","",","&CHAR(34)&"danger"&CHAR(34)&":"&CHAR(34)&"true"&CHAR(34)) &IF(M26="","",","&CHAR(34)&"explain"&CHAR(34)&":"&CHAR(34)&M26&CHAR(34)) &IF(N26="","",","&CHAR(34)&"explainImg"&CHAR(34)&":"&CHAR(34)&N26&CHAR(34)) &IF(O26="","",","&CHAR(34)&"shuffle"&CHAR(34)&":"&CHAR(34)&"false"&CHAR(34))&CHAR(125)&",") | R26: =CHAR(S26) -> _x001E_ | S26: =S25+1 -> 30
A27: Câu 7. Người lái xe được hiểu như thế nào là đúng? | C27: =IFERROR(COUNTIFS($A$1:A27,"Câu "&"*")-MID(A27,5,FIND(".",A27,1)-5),0) -> 0 | D27: =IF(LEFT(A27,3)="Câu",VALUE(MID(A27,5,FIND(".",A27,1)-5)),"") -> 7 | E27: =SUBSTITUTE(IF(LEFT(A27,3)="Câu",MID(A27,FIND(".",A27,1)+2,LEN(A27)),""),CHAR(34),CHAR(92)&CHAR(34)) -> Người lái xe được hiểu như thế nào là đúng? | G27: =SUBSTITUTE(B28,CHAR(34),CHAR(92)&CHAR(34)) -> Là người điều khiển xe cơ giới. | H27: =SUBSTITUTE(B29,CHAR(34),CHAR(92)&CHAR(34)) -> Là người điều khiển xe thô sơ. | I27: =SUBSTITUTE(IF(LEFT(A30,3)="Câu","",B30),CHAR(34),CHAR(92)&CHAR(34)) -> Là người điều khiển xe máy chuyên dùng. | J27: =SUBSTITUTE(IF(OR(LEFT(A31,3)="Câu",I27=""),"",IF(B31=0,"",B31)),CHAR(34),CHAR(92)&CHAR(34)) | K27: =SUBSTITUTE(SUBSTITUTE(SUBSTITUTE(SUBSTITUTE(IFERROR(VLOOKUP("Câu "&D27&".",dapan!$E:$J,6,0),""),"1","A"),"2","B"),"3","C"),"4","D") -> A | P27: =D27 -> 7 | Q27: =IF(D27="","",CHAR(123)&CHAR(34)&"num"&CHAR(34)&":"&P27&","&CHAR(34)&"id"&CHAR(34)&":"&D27&"," &CHAR(34)&"q"&CHAR(34)&":"&CHAR(34)&E27&CHAR(34)&"," &IF(F27="","",CHAR(34)&"img"&CHAR(34)&":"&CHAR(34)&F27&CHAR(34)&",") &CHAR(34)&"opts"&CHAR(34)&":"&CHAR(123)&CHAR(34)&"A"&CHAR(34)&":"&CHAR(34)&G27&CHAR(34)&","&CHAR(34)&"B"&CHAR(34)&":"&CHAR(34)&H27&CHAR(34) &IF(I27="","",","&CHAR(34)&"C"&CHAR(34)&":"&CHAR(34)&I27&CHAR(34))&IF(J27="","",","&CHAR(34)&"D"&CHAR(34)&":"&CHAR(34)&J27&CHAR(34))&CHAR(125)&"," &CHAR(34)&"answer"&CHAR(34)&":"&CHAR(34)&K27&CHAR(34) &IF(L27="","",","&CHAR(34)&"danger"&CHAR(34)&":"&CHAR(34)&"true"&CHAR(34)) &IF(M27="","",","&CHAR(34)&"explain"&CHAR(34)&":"&CHAR(34)&M27&CHAR(34)) &IF(N27="","",","&CHAR(34)&"explainImg"&CHAR(34)&":"&CHAR(34)&N27&CHAR(34)) &IF(O27="","",","&CHAR(34)&"shuffle"&CHAR(34)&":"&CHAR(34)&"false"&CHAR(34))&CHAR(125)&",") -> {"num":7,"id":7,"q":"Người lái xe được hiểu như thế nào là đúng?","opts":{"A":" Là người điều khiển xe cơ giới.","B":"Là người điều khiển xe thô sơ.","C":"Là người điều khiển xe máy chuyên dùng."},"answer":"A"}, | R27: =CHAR(S27) -> _x001F_ | S27: =S26+1 -> 31
A28: 1 | B28: Là người điều khiển xe cơ giới. | C28: =IFERROR(COUNTIFS($A$1:A28,"Câu "&"*")-MID(A28,5,FIND(".",A28,1)-5),0) -> 0 | D28: =IF(LEFT(A28,3)="Câu",VALUE(MID(A28,5,FIND(".",A28,1)-5)),"") | E28: =SUBSTITUTE(IF(LEFT(A28,3)="Câu",MID(A28,FIND(".",A28,1)+2,LEN(A28)),""),CHAR(34),CHAR(92)&CHAR(34)) | G28: =SUBSTITUTE(B29,CHAR(34),CHAR(92)&CHAR(34)) -> Là người điều khiển xe thô sơ. | H28: =SUBSTITUTE(B30,CHAR(34),CHAR(92)&CHAR(34)) -> Là người điều khiển xe máy chuyên dùng. | I28: =SUBSTITUTE(IF(LEFT(A31,3)="Câu","",B31),CHAR(34),CHAR(92)&CHAR(34)) | J28: =SUBSTITUTE(IF(OR(LEFT(A32,3)="Câu",I28=""),"",IF(B32=0,"",B32)),CHAR(34),CHAR(92)&CHAR(34)) | K28: =SUBSTITUTE(SUBSTITUTE(SUBSTITUTE(SUBSTITUTE(IFERROR(VLOOKUP("Câu "&D28&".",dapan!$E:$J,6,0),""),"1","A"),"2","B"),"3","C"),"4","D") | P28: =D28 | Q28: =IF(D28="","",CHAR(123)&CHAR(34)&"num"&CHAR(34)&":"&P28&","&CHAR(34)&"id"&CHAR(34)&":"&D28&"," &CHAR(34)&"q"&CHAR(34)&":"&CHAR(34)&E28&CHAR(34)&"," &IF(F28="","",CHAR(34)&"img"&CHAR(34)&":"&CHAR(34)&F28&CHAR(34)&",") &CHAR(34)&"opts"&CHAR(34)&":"&CHAR(123)&CHAR(34)&"A"&CHAR(34)&":"&CHAR(34)&G28&CHAR(34)&","&CHAR(34)&"B"&CHAR(34)&":"&CHAR(34)&H28&CHAR(34) &IF(I28="","",","&CHAR(34)&"C"&CHAR(34)&":"&CHAR(34)&I28&CHAR(34))&IF(J28="","",","&CHAR(34)&"D"&CHAR(34)&":"&CHAR(34)&J28&CHAR(34))&CHAR(125)&"," &CHAR(34)&"answer"&CHAR(34)&":"&CHAR(34)&K28&CHAR(34) &IF(L28="","",","&CHAR(34)&"danger"&CHAR(34)&":"&CHAR(34)&"true"&CHAR(34)) &IF(M28="","",","&CHAR(34)&"explain"&CHAR(34)&":"&CHAR(34)&M28&CHAR(34)) &IF(N28="","",","&CHAR(34)&"explainImg"&CHAR(34)&":"&CHAR(34)&N28&CHAR(34)) &IF(O28="","",","&CHAR(34)&"shuffle"&CHAR(34)&":"&CHAR(34)&"false"&CHAR(34))&CHAR(125)&",") | R28: =CHAR(S28) | S28: =S27+1 -> 32
A29: 2 | B29: Là người điều khiển xe thô sơ. | C29: =IFERROR(COUNTIFS($A$1:A29,"Câu "&"*")-MID(A29,5,FIND(".",A29,1)-5),0) -> 0 | D29: =IF(LEFT(A29,3)="Câu",VALUE(MID(A29,5,FIND(".",A29,1)-5)),"") | E29: =SUBSTITUTE(IF(LEFT(A29,3)="Câu",MID(A29,FIND(".",A29,1)+2,LEN(A29)),""),CHAR(34),CHAR(92)&CHAR(34)) | G29: =SUBSTITUTE(B30,CHAR(34),CHAR(92)&CHAR(34)) -> Là người điều khiển xe máy chuyên dùng. | H29: =SUBSTITUTE(B31,CHAR(34),CHAR(92)&CHAR(34)) | I29: =SUBSTITUTE(IF(LEFT(A32,3)="Câu","",B32),CHAR(34),CHAR(92)&CHAR(34)) -> Xe ô tô; máy kéo; xe mô tô hai bánh; xe mô tô ba bánh; xe gắn máy; xe cơ giới dùng cho người khuyết tật và xe máy chuyên dùng; xe đạp, xe đạp máy, xe đạp điện. | J29: =SUBSTITUTE(IF(OR(LEFT(A33,3)="Câu",I29=""),"",IF(B33=0,"",B33)),CHAR(34),CHAR(92)&CHAR(34)) -> Xe ô tô; rơ moóc được kéo bởi xe ô tô; sơ mi rơ moóc được kéo bởi ô tô đầu kéo; xe chở người bốn bánh có gắn động cơ; xe chở hàng bốn bánh có gắn động cơ; xe mô tô, xe gắn máy và các loại xe tương tự. | K29: =SUBSTITUTE(SUBSTITUTE(SUBSTITUTE(SUBSTITUTE(IFERROR(VLOOKUP("Câu "&D29&".",dapan!$E:$J,6,0),""),"1","A"),"2","B"),"3","C"),"4","D") | P29: =D29 | Q29: =IF(D29="","",CHAR(123)&CHAR(34)&"num"&CHAR(34)&":"&P29&","&CHAR(34)&"id"&CHAR(34)&":"&D29&"," &CHAR(34)&"q"&CHAR(34)&":"&CHAR(34)&E29&CHAR(34)&"," &IF(F29="","",CHAR(34)&"img"&CHAR(34)&":"&CHAR(34)&F29&CHAR(34)&",") &CHAR(34)&"opts"&CHAR(34)&":"&CHAR(123)&CHAR(34)&"A"&CHAR(34)&":"&CHAR(34)&G29&CHAR(34)&","&CHAR(34)&"B"&CHAR(34)&":"&CHAR(34)&H29&CHAR(34) &IF(I29="","",","&CHAR(34)&"C"&CHAR(34)&":"&CHAR(34)&I29&CHAR(34))&IF(J29="","",","&CHAR(34)&"D"&CHAR(34)&":"&CHAR(34)&J29&CHAR(34))&CHAR(125)&"," &CHAR(34)&"answer"&CHAR(34)&":"&CHAR(34)&K29&CHAR(34) &IF(L29="","",","&CHAR(34)&"danger"&CHAR(34)&":"&CHAR(34)&"true"&CHAR(34)) &IF(M29="","",","&CHAR(34)&"explain"&CHAR(34)&":"&CHAR(34)&M29&CHAR(34)) &IF(N29="","",","&CHAR(34)&"explainImg"&CHAR(34)&":"&CHAR(34)&N29&CHAR(34)) &IF(O29="","",","&CHAR(34)&"shuffle"&CHAR(34)&":"&CHAR(34)&"false"&CHAR(34))&CHAR(125)&",") | R29: =CHAR(S29) -> ! | S29: =S28+1 -> 33
A30: 3 | B30: Là người điều khiển xe máy chuyên dùng. | C30: =IFERROR(COUNTIFS($A$1:A30,"Câu "&"*")-MID(A30,5,FIND(".",A30,1)-5),0) -> 0 | D30: =IF(LEFT(A30,3)="Câu",VALUE(MID(A30,5,FIND(".",A30,1)-5)),"") | E30: =SUBSTITUTE(IF(LEFT(A30,3)="Câu",MID(A30,FIND(".",A30,1)+2,LEN(A30)),""),CHAR(34),CHAR(92)&CHAR(34)) | G30: =SUBSTITUTE(B31,CHAR(34),CHAR(92)&CHAR(34)) | H30: =SUBSTITUTE(B32,CHAR(34),CHAR(92)&CHAR(34)) -> Xe ô tô; máy kéo; xe mô tô hai bánh; xe mô tô ba bánh; xe gắn máy; xe cơ giới dùng cho người khuyết tật và xe máy chuyên dùng; xe đạp, xe đạp máy, xe đạp điện. | I30: =SUBSTITUTE(IF(LEFT(A33,3)="Câu","",B33),CHAR(34),CHAR(92)&CHAR(34)) -> Xe ô tô; rơ moóc được kéo bởi xe ô tô; sơ mi rơ moóc được kéo bởi ô tô đầu kéo; xe chở người bốn bánh có gắn động cơ; xe chở hàng bốn bánh có gắn động cơ; xe mô tô, xe gắn máy và các loại xe tương tự. | J30: =SUBSTITUTE(IF(OR(LEFT(A34,3)="Câu",I30=""),"",IF(B34=0,"",B34)),CHAR(34),CHAR(92)&CHAR(34)) | K30: =SUBSTITUTE(SUBSTITUTE(SUBSTITUTE(SUBSTITUTE(IFERROR(VLOOKUP("Câu "&D30&".",dapan!$E:$J,6,0),""),"1","A"),"2","B"),"3","C"),"4","D") | P30: =D30 | Q30: =IF(D30="","",CHAR(123)&CHAR(34)&"num"&CHAR(34)&":"&P30&","&CHAR(34)&"id"&CHAR(34)&":"&D30&"," &CHAR(34)&"q"&CHAR(34)&":"&CHAR(34)&E30&CHAR(34)&"," &IF(F30="","",CHAR(34)&"img"&CHAR(34)&":"&CHAR(34)&F30&CHAR(34)&",") &CHAR(34)&"opts"&CHAR(34)&":"&CHAR(123)&CHAR(34)&"A"&CHAR(34)&":"&CHAR(34)&G30&CHAR(34)&","&CHAR(34)&"B"&CHAR(34)&":"&CHAR(34)&H30&CHAR(34) &IF(I30="","",","&CHAR(34)&"C"&CHAR(34)&":"&CHAR(34)&I30&CHAR(34))&IF(J30="","",","&CHAR(34)&"D"&CHAR(34)&":"&CHAR(34)&J30&CHAR(34))&CHAR(125)&"," &CHAR(34)&"answer"&CHAR(34)&":"&CHAR(34)&K30&CHAR(34) &IF(L30="","",","&CHAR(34)&"danger"&CHAR(34)&":"&CHAR(34)&"true"&CHAR(34)) &IF(M30="","",","&CHAR(34)&"explain"&CHAR(34)&":"&CHAR(34)&M30&CHAR(34)) &IF(N30="","",","&CHAR(34)&"explainImg"&CHAR(34)&":"&CHAR(34)&N30&CHAR(34)) &IF(O30="","",","&CHAR(34)&"shuffle"&CHAR(34)&":"&CHAR(34)&"false"&CHAR(34))&CHAR(125)&",") | R30: =CHAR(S30) -> " | S30: =S29+1 -> 34
